Workbook
Name UPDATE: 'Data (Input)'!$E$1

Sheet Profit & Loss (Input)
A1: ='Data (Input)'!B1 -> INFOSYS LTD | H1: =UPDATE | M1: SCREENER.IN
A3: Narration | B3: ='Data (Input)'!B16 -> 42460 | C3: ='Data (Input)'!C16 -> 42825 | D3: ='Data (Input)'!D16 -> 43190 | E3: ='Data (Input)'!E16 -> 43555 | F3: ='Data (Input)'!F16 -> 43921 | G3: ='Data (Input)'!G16 -> 44286 | H3: ='Data (Input)'!H16 -> 44651 | I3: ='Data (Input)'!I16 -> 45016 | ... K3: ='Data (Input)'!K16 -> 45747 | L3: Trailing | M3: Best Case | N3: Worst Case
A4: Sales | B4: ='Data (Input)'!B17 -> 62441 | C4: ='Data (Input)'!C17 -> 68484 | D4: ='Data (Input)'!D17 -> 70522 | E4: ='Data (Input)'!E17 -> 82675 | F4: ='Data (Input)'!F17 -> 90791 | G4: ='Data (Input)'!G17 -> 100472 | H4: ='Data (Input)'!H17 -> 121641 | I4: ='Data (Input)'!I17 -> 146767 | ... K4: ='Data (Input)'!K17 -> 162990 | L4: =SUM('Quarters (Input)'!H4:K4) -> 173173 | M4: =$K4+M23*K4 -> 179688.91 | N4: =$K4+N23*L4 -> 173809.2
A5: Expenses | B5: =SUM('Data (Input)'!B18,'Data (Input)'!B20:B24, -1*'Data (Input)'!B19) -> 45362 | C5: =SUM('Data (Input)'!C18,'Data (Input)'!C20:C24, -1*'Data (Input)'!C19) -> 49880 | D5: =SUM('Data (Input)'!D18,'Data (Input)'!D20:D24, -1*'Data (Input)'!D19) -> 51700 | E5: =SUM('Data (Input)'!E18,'Data (Input)'!E20:E24, -1*'Data (Input)'!E19) -> 62505 | F5: =SUM('Data (Input)'!F18,'Data (Input)'!F20:F24, -1*'Data (Input)'!F19) -> 68524 | G5: =SUM('Data (Input)'!G18,'Data (Input)'!G20:G24, -1*'Data (Input)'!G19) -> 72583 | H5: =SUM('Data (Input)'!H18,'Data (Input)'!H20:H24, -1*'Data (Input)'!H19) -> 90150 | I5: =SUM('Data (Input)'!I18,'Data (Input)'!I20:I24, -1*'Data (Input)'!I19) -> 111637 | ... K5: =SUM('Data (Input)'!K18,'Data (Input)'!K20:K24, -1*'Data (Input)'!K19) -> 123754 | L5: =SUM('Quarters (Input)'!H5:K5) -> 132187 | M5: =M4-M6 -> 136730.88 | N5: =N4-N6 -> 132672.62
A6: Operating Profit | B6: =B4-B5 -> 17079 | C6: =C4-C5 -> 18604 | D6: =D4-D5 -> 18822 | E6: =E4-E5 -> 20170 | F6: =F4-F5 -> 22267 | G6: =G4-G5 -> 27889 | H6: =H4-H5 -> 31491 | I6: =I4-I5 -> 35130 | ... K6: =K4-K5 -> 39236 | L6: =SUM('Quarters (Input)'!H6:K6) -> 40986 | M6: =M4*M24 -> 42958.038 | N6: =N4*N24 -> 41136.573
A7: Other Income | B7: ='Data (Input)'!B25 -> 3120 | C7: ='Data (Input)'!C25 -> 3050 | D7: ='Data (Input)'!D25 -> 3311 | E7: ='Data (Input)'!E25 -> 2882 | F7: ='Data (Input)'!F25 -> 2803 | G7: ='Data (Input)'!G25 -> 2201 | H7: ='Data (Input)'!H25 -> 2295 | I7: ='Data (Input)'!I25 -> 2701 | ... K7: ='Data (Input)'!K25 -> 3600 | L7: =SUM('Quarters (Input)'!H7:K7) -> 3064 | M7: 0 | N7: 0
A8: Depreciation | B8: ='Data (Input)'!B26 -> 1459 | C8: ='Data (Input)'!C26 -> 1703 | D8: ='Data (Input)'!D26 -> 1863 | E8: ='Data (Input)'!E26 -> 2011 | F8: ='Data (Input)'!F26 -> 2893 | G8: ='Data (Input)'!G26 -> 3267 | H8: ='Data (Input)'!H26 -> 3476 | I8: ='Data (Input)'!I26 -> 4225 | ... K8: ='Data (Input)'!K26 -> 4812 | L8: =SUM('Quarters (Input)'!H8:K8) -> 4776 | M8: =+$L8 -> 4776 | N8: =+$L8 -> 4776
A9: Interest | B9: ='Data (Input)'!B27 -> 0 | C9: ='Data (Input)'!C27 -> 0 | D9: ='Data (Input)'!D27 -> 0 | E9: ='Data (Input)'!E27 -> 0 | F9: ='Data (Input)'!F27 -> 170 | G9: ='Data (Input)'!G27 -> 195 | H9: ='Data (Input)'!H27 -> 200 | I9: ='Data (Input)'!I27 -> 284 | ... K9: ='Data (Input)'!K27 -> 416 | L9: =SUM('Quarters (Input)'!H9:K9) -> 413 | M9: =+$L9 -> 413 | N9: =+$L9 -> 413
A10: Profit before tax | B10: ='Data (Input)'!B28 -> 18740 | C10: ='Data (Input)'!C28 -> 19951 | D10: ='Data (Input)'!D28 -> 20270 | E10: ='Data (Input)'!E28 -> 21041 | F10: ='Data (Input)'!F28 -> 22007 | G10: ='Data (Input)'!G28 -> 26628 | H10: ='Data (Input)'!H28 -> 30110 | I10: ='Data (Input)'!I28 -> 33322 | ... K10: ='Data (Input)'!K28 -> 37608 | L10: =SUM('Quarters (Input)'!H10:K10) -> 38861 | M10: =M6+M7-SUM(M8:M9) -> 37769.038 | N10: =N6+N7-SUM(N8:N9) -> 35947.573
A11: Tax | B11: ='Data (Input)'!B29 -> 5251 | C11: ='Data (Input)'!C29 -> 5598 | D11: ='Data (Input)'!D29 -> 4241 | E11: ='Data (Input)'!E29 -> 5631 | F11: ='Data (Input)'!F29 -> 5368 | G11: ='Data (Input)'!G29 -> 7205 | H11: ='Data (Input)'!H29 -> 7964 | I11: ='Data (Input)'!I29 -> 9214 | ... K11: ='Data (Input)'!K29 -> 10858 | L11: =SUM('Quarters (Input)'!H11:K11) -> 10858 | M11: =IF($L10>0,$L11/$L10,0) -> 0.27940609 | N11: =IF($L10>0,$L11/$L10,0) -> 0.27940609
A12: Net profit | B12: ='Data (Input)'!B30 -> 13489 | C12: ='Data (Input)'!C30 -> 14353 | D12: ='Data (Input)'!D30 -> 16029 | E12: ='Data (Input)'!E30 -> 15404 | F12: ='Data (Input)'!F30 -> 16594 | G12: ='Data (Input)'!G30 -> 19351 | H12: ='Data (Input)'!H30 -> 22110 | I12: ='Data (Input)'!I30 -> 24095 | ... K12: ='Data (Input)'!K30 -> 26713 | L12: =SUM('Quarters (Input)'!H12:K12) -> 27972 | M12: =M10-M11*M10 -> 27216.139 | N12: =N10-N11*N10 -> 25903.602
A13: EPS | B13: =IF('Data (Input)'!B93>0,B12/'Data (Input)'!B93,0) -> 29.362851 | C13: =IF('Data (Input)'!C93>0,C12/'Data (Input)'!C93,0) -> 31.243606 | D13: =IF('Data (Input)'!D93>0,D12/'Data (Input)'!D93,0) -> 36.694748 | E13: =IF('Data (Input)'!E93>0,E12/'Data (Input)'!E93,0) -> 35.258303 | F13: =IF('Data (Input)'!F93>0,F12/'Data (Input)'!F93,0) -> 38.962198 | G13: =IF('Data (Input)'!G93>0,G12/'Data (Input)'!G93,0) -> 45.41742 | H13: =IF('Data (Input)'!H93>0,H12/'Data (Input)'!H93,0) -> 52.559013 | I13: =IF('Data (Input)'!I93>0,I12/'Data (Input)'!I93,0) -> 58.079834 | ... K13: =IF('Data (Input)'!K93>0,K12/'Data (Input)'!K93,0) -> 64.317531 | L13: =IF('Data (Input)'!$B6>0,'Profit & Loss (Input)'!L12/'Data (Input)'!$B6,0) -> 68.987036 | M13: =IF('Data (Input)'!$B6>0,'Profit & Loss (Input)'!M12/'Data (Input)'!$B6,0) -> 67.122864 | N13: =IF('Data (Input)'!$B6>0,'Profit & Loss (Input)'!N12/'Data (Input)'!$B6,0) -> 63.885769
A14: Price to earning | B14: =IF(B15>0,B15/B13,"") -> 20.745601 | C14: =IF(C15>0,C15/C13,"") -> 16.359507 | D14: =IF(D15>0,D15/D13,"") -> 15.421825 | E14: =IF(E15>0,E15/E13,"") -> 21.097158 | F14: =IF(F15>0,F15/F13,"") -> 16.464677 | G14: =IF(G15>0,G15/G13,"") -> 30.121702 | H14: =IF(H15>0,H15/H13,"") -> 36.280171 | I14: =IF(I15>0,I15/I13,"") -> 24.585986 | ... K14: =IF(K15>0,K15/K13,"") -> 24.420247 | L14: =IF(L13>0,L15/L13,0) -> 23.787078 | M14: =M25 -> 24.124314 | N14: =N25 -> 22.9989
A15: Price | B15: ='Data (Input)'!B90 -> 609.15 | C15: ='Data (Input)'!C90 -> 511.13 | D15: ='Data (Input)'!D90 -> 565.9 | E15: ='Data (Input)'!E90 -> 743.85 | F15: ='Data (Input)'!F90 -> 641.5 | G15: ='Data (Input)'!G90 -> 1368.05 | H15: ='Data (Input)'!H90 -> 1906.85 | I15: ='Data (Input)'!I90 -> 1427.95 | ... K15: ='Data (Input)'!K90 -> 1570.65 | L15: ='Data (Input)'!B8 -> 1641 | M15: =M13*M14 -> 1619.293 | N15: =N13*N14 -> 1469.3024
A17: RATIOS:
A18: Dividend Payout | B18: =IF('Data (Input)'!B30>0, 'Data (Input)'!B31/'Data (Input)'!B30, 0) -> 0.41132775 | C18: =IF('Data (Input)'!C30>0, 'Data (Input)'!C31/'Data (Input)'!C30, 0) -> 0.41047865 | D18: =IF('Data (Input)'!D30>0, 'Data (Input)'!D31/'Data (Input)'!D30, 0) -> 0.59052966 | E18: =IF('Data (Input)'!E30>0, 'Data (Input)'!E31/'Data (Input)'!E30, 0) -> 0.59870813 | F18: =IF('Data (Input)'!F30>0, 'Data (Input)'!F31/'Data (Input)'!F30, 0) -> 0.44757141 | G18: =IF('Data (Input)'!G30>0, 'Data (Input)'!G31/'Data (Input)'!G30, 0) -> 0.59271355 | H18: =IF('Data (Input)'!H30>0, 'Data (Input)'!H31/'Data (Input)'!H30, 0) -> 0.58831298 | I18: =IF('Data (Input)'!I30>0, 'Data (Input)'!I31/'Data (Input)'!I30, 0) -> 0.58390537 | ... K18: =IF('Data (Input)'!K30>0, 'Data (Input)'!K31/'Data (Input)'!K30, 0) -> 0.66738292
A19: OPM | B19: =IF(B6>0,B6/B4,0) -> 0.2735222 | C19: =IF(C6>0,C6/C4,0) -> 0.27165469 | D19: =IF(D6>0,D6/D4,0) -> 0.26689544 | E19: =IF(E6>0,E6/E4,0) -> 0.24396734 | F19: =IF(F6>0,F6/F4,0) -> 0.24525559 | G19: =IF(G6>0,G6/G4,0) -> 0.27757982 | H19: =IF(H6>0,H6/H4,0) -> 0.25888475 | I19: =IF(I6>0,I6/I4,0) -> 0.23935898 | ... L19: =IF(L6>0,L6/L4,0) -> 0.23667662
G22: TRENDS: | H22: 10 YEARS | I22: 7 YEARS | J22: 5 YEARS | K22: 3 YEARS | L22: RECENT | M22: BEST | N22: WORST
G23: Sales Growth | H23: =IF(B4=0,"",POWER($K4/B4,1/9)-1) -> 0.11249742 | I23: =IF(D4=0,"",POWER($K4/D4,1/7)-1) -> 0.12713678 | J23: =IF(F4=0,"",POWER($K4/F4,1/5)-1) -> 0.12414836 | K23: =IF(H4=0,"",POWER($K4/H4, 1/3)-1) -> 0.10245362 | L23: =IF(ISERROR(MAX(IF(J4=0,"",(K4-J4)/J4),IF(K4=0,"",(L4-K4)/K4))),"",MAX(IF(J4=0,"",(K4-J4)/J4),IF(K4=0,"",(L4-K4)/K4))) -> 0.062476226 | M23: =MAX(K23:L23) -> 0.10245362 | N23: =MIN(H23:L23) -> 0.062476226
G24: OPM | H24: =IF(SUM(B4:$K$4)=0,"",SUMPRODUCT(B19:$K$19,B4:$K$4)/SUM(B4:$K$4)) -> 0.25188575 | I24: =IF(SUM(E4:$K$4)=0,"",SUMPRODUCT(E19:$K$19,E4:$K$4)/SUM(E4:$K$4)) -> 0.24750467 | J24: =IF(SUM(G4:$K$4)=0,"",SUMPRODUCT(G19:$K$19,G4:$K$4)/SUM(G4:$K$4)) -> 0.24822913 | K24: =IF(SUM(I4:$K$4)=0, "", SUMPRODUCT(I19:$K$19,I4:$K$4)/SUM(I4:$K$4)) -> 0.23906894 | L24: =L19 -> 0.23667662 | M24: =MAX(K24:L24) -> 0.23906894 | N24: =MIN(H24:L24) -> 0.23667662
G25: Price to Earning | H25: =IF(ISERROR(AVERAGEIF(B14:$L14,">0")),"",AVERAGEIF(B14:$L14,">0")) -> 22.9989 | I25: =IF(ISERROR(AVERAGEIF(E14:$L14,">0")),"",AVERAGEIF(E14:$L14,">0")) -> 25.057621 | J25: =IF(ISERROR(AVERAGEIF(G14:$L14,">0")),"",AVERAGEIF(G14:$L14,">0")) -> 27.149855 | K25: =IF(ISERROR(AVERAGEIF(I14:$L14,">0")),"",AVERAGEIF(I14:$L14,">0")) -> 24.124314 | L25: =L14 -> 23.787078 | M25: =MAX(K25:L25) -> 24.124314 | N25: =MIN(H25:L25) -> 22.9989

Sheet Quarters (Input)
A1: ='Profit & Loss (Input)'!A1 -> INFOSYS LTD | E1: =UPDATE | J1: SCREENER.IN
A3: Narration | B3: ='Data (Input)'!B41 -> 45199 | C3: ='Data (Input)'!C41 -> 45291 | D3: ='Data (Input)'!D41 -> 45382 | E3: ='Data (Input)'!E41 -> 45473 | F3: ='Data (Input)'!F41 -> 45565 | G3: ='Data (Input)'!G41 -> 45657 | H3: ='Data (Input)'!H41 -> 45747 | I3: ='Data (Input)'!I41 -> 45838 | ... K3: ='Data (Input)'!K41 -> 46022
A4: Sales | B4: ='Data (Input)'!B42 -> 38994 | C4: ='Data (Input)'!C42 -> 38821 | D4: ='Data (Input)'!D42 -> 37923 | E4: ='Data (Input)'!E42 -> 39315 | F4: ='Data (Input)'!F42 -> 40986 | G4: ='Data (Input)'!G42 -> 41764 | H4: ='Data (Input)'!H42 -> 40925 | I4: ='Data (Input)'!I42 -> 42279 | ... K4: ='Data (Input)'!K42 -> 45479
A5: Expenses | B5: ='Data (Input)'!B43 -> 29554 | C5: ='Data (Input)'!C43 -> 29684 | D5: ='Data (Input)'!D43 -> 29139 | E5: ='Data (Input)'!E43 -> 29878 | F5: ='Data (Input)'!F43 -> 31177 | G5: ='Data (Input)'!G43 -> 31649 | H5: ='Data (Input)'!H43 -> 31051 | I5: ='Data (Input)'!I43 -> 32336 | ... K5: ='Data (Input)'!K43 -> 34845
A6: Operating Profit | B6: ='Data (Input)'!B50 -> 9440 | C6: ='Data (Input)'!C50 -> 9137 | D6: ='Data (Input)'!D50 -> 8784 | E6: ='Data (Input)'!E50 -> 9437 | F6: ='Data (Input)'!F50 -> 9809 | G6: ='Data (Input)'!G50 -> 10115 | H6: ='Data (Input)'!H50 -> 9874 | I6: ='Data (Input)'!I50 -> 9943 | ... K6: ='Data (Input)'!K50 -> 10634
A7: Other Income | B7: ='Data (Input)'!B44 -> 632 | C7: ='Data (Input)'!C44 -> 789 | D7: ='Data (Input)'!D44 -> 2729 | E7: ='Data (Input)'!E44 -> 838 | F7: ='Data (Input)'!F44 -> 712 | G7: ='Data (Input)'!G44 -> 859 | H7: ='Data (Input)'!H44 -> 1190 | I7: ='Data (Input)'!I44 -> 1042 | ... K7: ='Data (Input)'!K44 -> -150
A8: Depreciation | B8: ='Data (Input)'!B45 -> 1166 | C8: ='Data (Input)'!C45 -> 1176 | D8: ='Data (Input)'!D45 -> 1163 | E8: ='Data (Input)'!E45 -> 1149 | F8: ='Data (Input)'!F45 -> 1160 | G8: ='Data (Input)'!G45 -> 1203 | H8: ='Data (Input)'!H45 -> 1299 | I8: ='Data (Input)'!I45 -> 1140 | ... K8: ='Data (Input)'!K45 -> 1155
A9: Interest | B9: ='Data (Input)'!B46 -> 138 | C9: ='Data (Input)'!C46 -> 131 | D9: ='Data (Input)'!D46 -> 110 | E9: ='Data (Input)'!E46 -> 105 | F9: ='Data (Input)'!F46 -> 108 | G9: ='Data (Input)'!G46 -> 101 | H9: ='Data (Input)'!H46 -> 102 | I9: ='Data (Input)'!I46 -> 105 | ... K9: ='Data (Input)'!K46 -> 100
A10: Profit before tax | B10: ='Data (Input)'!B47 -> 8768 | C10: ='Data (Input)'!C47 -> 8619 | D10: ='Data (Input)'!D47 -> 10240 | E10: ='Data (Input)'!E47 -> 9021 | F10: ='Data (Input)'!F47 -> 9253 | G10: ='Data (Input)'!G47 -> 9670 | H10: ='Data (Input)'!H47 -> 9663 | I10: ='Data (Input)'!I47 -> 9740 | ... K10: ='Data (Input)'!K47 -> 9229
A11: Tax | B11: ='Data (Input)'!B48 -> 2553 | C11: ='Data (Input)'!C48 -> 2506 | D11: ='Data (Input)'!D48 -> 2265 | E11: ='Data (Input)'!E48 -> 2647 | F11: ='Data (Input)'!F48 -> 2737 | G11: ='Data (Input)'!G48 -> 2848 | H11: ='Data (Input)'!H48 -> 2625 | I11: ='Data (Input)'!I48 -> 2816 | ... K11: ='Data (Input)'!K48 -> 2563
A12: Net profit | B12: ='Data (Input)'!B49 -> 6212 | C12: ='Data (Input)'!C49 -> 6106 | D12: ='Data (Input)'!D49 -> 7969 | E12: ='Data (Input)'!E49 -> 6368 | F12: ='Data (Input)'!F49 -> 6506 | G12: ='Data (Input)'!G49 -> 6806 | H12: ='Data (Input)'!H49 -> 7033 | I12: ='Data (Input)'!I49 -> 6921 | ... K12: ='Data (Input)'!K49 -> 6654
A14: OPM | B14: =IF(B4>0,B6/B4,"") -> 0.24208853 | C14: =IF(C4>0,C6/C4,"") -> 0.2353623 | D14: =IF(D4>0,D6/D4,"") -> 0.23162724 | E14: =IF(E4>0,E6/E4,"") -> 0.24003561 | F14: =IF(F4>0,F6/F4,"") -> 0.23932562 | G14: =IF(G4>0,G6/G4,"") -> 0.24219423 | H14: =IF(H4>0,H6/H4,"") -> 0.24127062 | I14: =IF(I4>0,I6/I4,"") -> 0.23517586 | ... K14: =IF(K4>0,K6/K4,"") -> 0.2338222

Sheet Cash Flow (Input)
A1: ='Balance Sheet (Input)'!A1 -> INFOSYS LTD | E1: =UPDATE | J1: SCREENER.IN
A3: Narration | B3: ='Data (Input)'!B81 -> 42460 | C3: ='Data (Input)'!C81 -> 42825 | D3: ='Data (Input)'!D81 -> 43190 | E3: ='Data (Input)'!E81 -> 43555 | F3: ='Data (Input)'!F81 -> 43921 | G3: ='Data (Input)'!G81 -> 44286 | H3: ='Data (Input)'!H81 -> 44651 | I3: ='Data (Input)'!I81 -> 45016 | ... K3: ='Data (Input)'!K81 -> 45747
A4: Cash from Operating Activity | B4: ='Data (Input)'!B82 -> 10028 | C4: ='Data (Input)'!C82 -> 11531 | D4: ='Data (Input)'!D82 -> 13218 | E4: ='Data (Input)'!E82 -> 14841 | F4: ='Data (Input)'!F82 -> 17003 | G4: ='Data (Input)'!G82 -> 23224 | H4: ='Data (Input)'!H82 -> 23885 | I4: ='Data (Input)'!I82 -> 22467 | ... K4: ='Data (Input)'!K82 -> 35694
A5: Cash from Investing Activity | B5: ='Data (Input)'!B83 -> -885 | C5: ='Data (Input)'!C83 -> -14664 | D5: ='Data (Input)'!D83 -> 4533 | E5: ='Data (Input)'!E83 -> -632 | F5: ='Data (Input)'!F83 -> -331 | G5: ='Data (Input)'!G83 -> -7373 | H5: ='Data (Input)'!H83 -> -6485 | I5: ='Data (Input)'!I83 -> -1071 | ... K5: ='Data (Input)'!K83 -> -1864
A6: Cash from Financing Activity | B6: ='Data (Input)'!B84 -> -6813 | C6: ='Data (Input)'!C84 -> -6939 | D6: ='Data (Input)'!D84 -> -20505 | E6: ='Data (Input)'!E84 -> -14512 | F6: ='Data (Input)'!F84 -> -17591 | G6: ='Data (Input)'!G84 -> -9786 | H6: ='Data (Input)'!H84 -> -24642 | I6: ='Data (Input)'!I84 -> -26695 | ... K6: ='Data (Input)'!K84 -> -24161
A7: Net Cash Flow | B7: ='Data (Input)'!B85 -> 2330 | C7: ='Data (Input)'!C85 -> -10072 | D7: ='Data (Input)'!D85 -> -2754 | E7: ='Data (Input)'!E85 -> -303 | F7: ='Data (Input)'!F85 -> -919 | G7: ='Data (Input)'!G85 -> 6065 | H7: ='Data (Input)'!H85 -> -7242 | I7: ='Data (Input)'!I85 -> -5299 | ... K7: ='Data (Input)'!K85 -> 9669

Sheet Data (Input)
A1: COMPANY NAME | B1: INFOSYS LTD | E1: =IF(B2<>B3, "A NEW VERSION OF THE WORKSHEET IS AVAILABLE", "")
A2: LATEST VERSION | B2: 2.1 | E2: PLEASE DO NOT MAKE ANY CHANGES TO THIS SHEET
A3: CURRENT VERSION | B3: 2.1
A5: META
A6: Number of shares | B6: =IF(B9>0, B9/B8, 0) -> 405.46748
A7: Face Value | B7: 5
A8: Current Price | B8: 1641
A9: Market Capitalization | B9: 665372.14
A15: PROFIT & LOSS
A16: Report Date | B16: 42460 | C16: 42825 | D16: 43190 | E16: 43555 | F16: 43921 | G16: 44286 | H16: 44651 | I16: 45016 | J16: 45382 | K16: 45747
A17: Sales | B17: 62441 | C17: 68484 | D17: 70522 | E17: 82675 | F17: 90791 | G17: 100472 | H17: 121641 | I17: 146767 | J17: 153670 | K17: 162990
A18: Raw Material Cost
A19: Change in Inventory
A20: Power and Fuel | B20: 217 | C20: 228 | D20: 207 | E20: 221 | F20: 229 | G20: 143 | H20: 132 | I20: 176 | J20: 199 | K20: 222
A21: Other Mfr. Exp | B21: 5860 | C21: 6712 | D21: 7286 | E21: 9902 | F21: 11086 | G21: 12800 | H21: 20690 | I21: 26330 | J21: 27195 | K21: 30395
A22: Employee Cost | B22: 34415 | C22: 37669 | D22: 38902 | E22: 45323 | F22: 50895 | G22: 55547 | H22: 63997 | I22: 78374 | J22: 82636 | K22: 85968
A23: Selling and admin | B23: 4441 | C23: 4584 | D23: 4585 | E23: 5553 | F23: 5375 | G23: 3194 | H23: 4305 | I23: 5300 | J23: 5705 | K23: 6039
A24: Other Expenses | B24: 429 | C24: 687 | D24: 720 | E24: 1506 | F24: 939 | G24: 899 | H24: 1026 | I24: 1457 | J24: 1510 | K24: 1130
A25: Other Income | B25: 3120 | C25: 3050 | D25: 3311 | E25: 2882 | F25: 2803 | G25: 2201 | H25: 2295 | I25: 2701 | J25: 4711 | K25: 3600
A26: Depreciation | B26: 1459 | C26: 1703 | D26: 1863 | E26: 2011 | F26: 2893 | G26: 3267 | H26: 3476 | I26: 4225 | J26: 4678 | K26: 4812
A27: Interest | F27: 170 | G27: 195 | H27: 200 | I27: 284 | J27: 470 | K27: 416
A28: Profit before tax | B28: 18740 | C28: 19951 | D28: 20270 | E28: 21041 | F28: 22007 | G28: 26628 | H28: 30110 | I28: 33322 | J28: 35988 | K28: 37608
A29: Tax | B29: 5251 | C29: 5598 | D29: 4241 | E29: 5631 | F29: 5368 | G29: 7205 | H29: 7964 | I29: 9214 | J29: 9740 | K29: 10858
A30: Net profit | B30: 13489 | C30: 14353 | D30: 16029 | E30: 15404 | F30: 16594 | G30: 19351 | H30: 22110 | I30: 24095 | J30: 26233 | K30: 26713
A31: Dividend Amount | B31: 5548.4 | C31: 5891.6 | D31: 9465.6 | E31: 9222.5 | F31: 7427 | G31: 11469.6 | H31: 13007.6 | I31: 14069.2 | J31: 19053.2 | K31: 17827.8
A40: Quarters
A41: Report Date | B41: 45199 | C41: 45291 | D41: 45382 | E41: 45473 | F41: 45565 | G41: 45657 | H41: 45747 | I41: 45838 | J41: 45930 | K41: 46022
A42: Sales | B42: 38994 | C42: 38821 | D42: 37923 | E42: 39315 | F42: 40986 | G42: 41764 | H42: 40925 | I42: 42279 | J42: 44490 | K42: 45479
A43: Expenses | B43: 29554 | C43: 29684 | D43: 29139 | E43: 29878 | F43: 31177 | G43: 31649 | H43: 31051 | I43: 32336 | J43: 33955 | K43: 34845
A44: Other Income | B44: 632 | C44: 789 | D44: 2729 | E44: 838 | F44: 712 | G44: 859 | H44: 1190 | I44: 1042 | J44: 982 | K44: -150
A45: Depreciation | B45: 1166 | C45: 1176 | D45: 1163 | E45: 1149 | F45: 1160 | G45: 1203 | H45: 1299 | I45: 1140 | J45: 1182 | K45: 1155
A46: Interest | B46: 138 | C46: 131 | D46: 110 | E46: 105 | F46: 108 | G46: 101 | H46: 102 | I46: 105 | J46: 106 | K46: 100
A47: Profit before tax | B47: 8768 | C47: 8619 | D47: 10240 | E47: 9021 | F47: 9253 | G47: 9670 | H47: 9663 | I47: 9740 | J47: 10229 | K47: 9229
A48: Tax | B48: 2553 | C48: 2506 | D48: 2265 | E48: 2647 | F48: 2737 | G48: 2848 | H48: 2625 | I48: 2816 | J48: 2854 | K48: 2563
A49: Net profit | B49: 6212 | C49: 6106 | D49: 7969 | E49: 6368 | F49: 6506 | G49: 6806 | H49: 7033 | I49: 6921 | J49: 7364 | K49: 6654
A50: Operating Profit | B50: 9440 | C50: 9137 | D50: 8784 | E50: 9437 | F50: 9809 | G50: 10115 | H50: 9874 | I50: 9943 | J50: 10535 | K50: 10634
A55: BALANCE SHEET
A56: Report Date | B56: 42460 | C56: 42825 | D56: 43190 | E56: 43555 | F56: 43921 | G56: 44286 | H56: 44651 | I56: 45016 | J56: 45382 | K56: 45747
A57: Equity Share Capital | B57: 1144 | C57: 1144 | D57: 1088 | E57: 2170 | F57: 2122 | G57: 2124 | H57: 2098 | I57: 2069 | J57: 2071 | K57: 2073
A58: Reserves | B58: 60600 | C58: 67838 | D58: 63835 | E58: 62778 | F58: 63328 | G58: 74227 | H58: 73252 | I58: 73338 | J58: 86045 | K58: 93745
...

Sheet Balance Sheet (Input)
A1: ='Profit & Loss (Input)'!A1 -> INFOSYS LTD | E1: =UPDATE | J1: SCREENER.IN
A3: Narration | B3: ='Data (Input)'!B56 -> 42460 | C3: ='Data (Input)'!C56 -> 42825 | D3: ='Data (Input)'!D56 -> 43190 | E3: ='Data (Input)'!E56 -> 43555 | F3: ='Data (Input)'!F56 -> 43921 | G3: ='Data (Input)'!G56 -> 44286 | H3: ='Data (Input)'!H56 -> 44651 | I3: ='Data (Input)'!I56 -> 45016 | ... K3: ='Data (Input)'!K56 -> 45747
A4: Equity Share Capital | B4: ='Data (Input)'!B57 -> 1144 | C4: ='Data (Input)'!C57 -> 1144 | D4: ='Data (Input)'!D57 -> 1088 | E4: ='Data (Input)'!E57 -> 2170 | F4: ='Data (Input)'!F57 -> 2122 | G4: ='Data (Input)'!G57 -> 2124 | H4: ='Data (Input)'!H57 -> 2098 | I4: ='Data (Input)'!I57 -> 2069 | ... K4: ='Data (Input)'!K57 -> 2073
A5: Reserves | B5: ='Data (Input)'!B58 -> 60600 | C5: ='Data (Input)'!C58 -> 67838 | D5: ='Data (Input)'!D58 -> 63835 | E5: ='Data (Input)'!E58 -> 62778 | F5: ='Data (Input)'!F58 -> 63328 | G5: ='Data (Input)'!G58 -> 74227 | H5: ='Data (Input)'!H58 -> 73252 | I5: ='Data (Input)'!I58 -> 73338 | ... K5: ='Data (Input)'!K58 -> 93745
A6: Borrowings | B6: ='Data (Input)'!B59 -> 0 | C6: ='Data (Input)'!C59 -> 0 | D6: ='Data (Input)'!D59 -> 0 | E6: ='Data (Input)'!E59 -> 0 | F6: ='Data (Input)'!F59 -> 4633 | G6: ='Data (Input)'!G59 -> 5325 | H6: ='Data (Input)'!H59 -> 5474 | I6: ='Data (Input)'!I59 -> 8299 | ... K6: ='Data (Input)'!K59 -> 8227
A7: Other Liabilities | B7: ='Data (Input)'!B60 -> 13354 | C7: ='Data (Input)'!C60 -> 14166 | D7: ='Data (Input)'!D60 -> 14426 | E7: ='Data (Input)'!E60 -> 19118 | F7: ='Data (Input)'!F60 -> 21717 | G7: ='Data (Input)'!G60 -> 25835 | H7: ='Data (Input)'!H60 -> 35905 | I7: ='Data (Input)'!I60 -> 40890 | ... K7: ='Data (Input)'!K60 -> 43750
A8: Total | B8: ='Data (Input)'!B61 -> 75098 | C8: ='Data (Input)'!C61 -> 83148 | D8: ='Data (Input)'!D61 -> 79349 | E8: ='Data (Input)'!E61 -> 84066 | F8: ='Data (Input)'!F61 -> 91800 | G8: ='Data (Input)'!G61 -> 107511 | H8: ='Data (Input)'!H61 -> 116729 | I8: ='Data (Input)'!I61 -> 124596 | ... K8: ='Data (Input)'!K61 -> 147795
A10: Net Block | B10: ='Data (Input)'!B62 -> 13386 | C10: ='Data (Input)'!C62 -> 14179 | D10: ='Data (Input)'!D62 -> 12574 | E10: ='Data (Input)'!E62 -> 15710 | F10: ='Data (Input)'!F62 -> 23789 | G10: ='Data (Input)'!G62 -> 25505 | H10: ='Data (Input)'!H62 -> 25800 | I10: ='Data (Input)'!I62 -> 29225 | ... K10: ='Data (Input)'!K62 -> 30961
A11: Capital Work in Progress | B11: ='Data (Input)'!B63 -> 960 | C11: ='Data (Input)'!C63 -> 1365 | D11: ='Data (Input)'!D63 -> 1606 | E11: ='Data (Input)'!E63 -> 1388 | F11: ='Data (Input)'!F63 -> 954 | G11: ='Data (Input)'!G63 -> 922 | H11: ='Data (Input)'!H63 -> 416 | I11: ='Data (Input)'!I63 -> 288 | ... K11: ='Data (Input)'!K63 -> 814
A12: Investments | B12: ='Data (Input)'!B64 -> 1892 | C12: ='Data (Input)'!C64 -> 16423 | D12: ='Data (Input)'!D64 -> 12163 | E12: ='Data (Input)'!E64 -> 11261 | F12: ='Data (Input)'!F64 -> 8792 | G12: ='Data (Input)'!G64 -> 14205 | H12: ='Data (Input)'!H64 -> 20324 | I12: ='Data (Input)'!I64 -> 19478 | ... K12: ='Data (Input)'!K64 -> 23541
A13: Other Assets | B13: ='Data (Input)'!B65 -> 58860 | C13: ='Data (Input)'!C65 -> 51181 | D13: ='Data (Input)'!D65 -> 53006 | E13: ='Data (Input)'!E65 -> 55707 | F13: ='Data (Input)'!F65 -> 58265 | G13: ='Data (Input)'!G65 -> 66879 | H13: ='Data (Input)'!H65 -> 70189 | I13: ='Data (Input)'!I65 -> 75605 | ... K13: ='Data (Input)'!K65 -> 92479
A14: Total | B14: ='Data (Input)'!B66 -> 75098 | C14: ='Data (Input)'!C66 -> 83148 | D14: ='Data (Input)'!D66 -> 79349 | E14: ='Data (Input)'!E66 -> 84066 | F14: ='Data (Input)'!F66 -> 91800 | G14: ='Data (Input)'!G66 -> 107511 | H14: ='Data (Input)'!H66 -> 116729 | I14: ='Data (Input)'!I66 -> 124596 | ... K14: ='Data (Input)'!K66 -> 147795
A16: Working Capital | B16: =B13-B7 -> 45506 | C16: =C13-C7 -> 37015 | D16: =D13-D7 -> 38580 | E16: =E13-E7 -> 36589 | F16: =F13-F7 -> 36548 | G16: =G13-G7 -> 41044 | H16: =H13-H7 -> 34284 | I16: =I13-I7 -> 34715 | ... K16: =K13-K7 -> 48729
A17: Debtors | B17: ='Data (Input)'!B67 -> 11330 | C17: ='Data (Input)'!C67 -> 12322 | D17: ='Data (Input)'!D67 -> 13142 | E17: ='Data (Input)'!E67 -> 14827 | F17: ='Data (Input)'!F67 -> 18487 | G17: ='Data (Input)'!G67 -> 19294 | H17: ='Data (Input)'!H67 -> 22698 | I17: ='Data (Input)'!I67 -> 25424 | ... K17: ='Data (Input)'!K67 -> 31158
A18: Inventory | B18: ='Data (Input)'!B68 -> 0 | C18: ='Data (Input)'!C68 -> 0 | D18: ='Data (Input)'!D68 -> 0 | E18: ='Data (Input)'!E68 -> 0 | F18: ='Data (Input)'!F68 -> 0 | G18: ='Data (Input)'!G68 -> 0 | H18: ='Data (Input)'!H68 -> 0 | I18: ='Data (Input)'!I68 -> 0 | ... K18: ='Data (Input)'!K68 -> 0
A20: Debtor Days | B20: =IF('Profit & Loss (Input)'!B4>0,'Balance Sheet (Input)'!B17/('Profit & Loss (Input)'!B4/365),0) -> 66.229721 | C20: =IF('Profit & Loss (Input)'!C4>0,'Balance Sheet (Input)'!C17/('Profit & Loss (Input)'!C4/365),0) -> 65.672712 | D20: =IF('Profit & Loss (Input)'!D4>0,'Balance Sheet (Input)'!D17/('Profit & Loss (Input)'!D4/365),0) -> 68.018916 | E20: =IF('Profit & Loss (Input)'!E4>0,'Balance Sheet (Input)'!E17/('Profit & Loss (Input)'!E4/365),0) -> 65.459389 | F20: =IF('Profit & Loss (Input)'!F4>0,'Balance Sheet (Input)'!F17/('Profit & Loss (Input)'!F4/365),0) -> 74.321849 | G20: =IF('Profit & Loss (Input)'!G4>0,'Balance Sheet (Input)'!G17/('Profit & Loss (Input)'!G4/365),0) -> 70.092265 | H20: =IF('Profit & Loss (Input)'!H4>0,'Balance Sheet (Input)'!H17/('Profit & Loss (Input)'!H4/365),0) -> 68.108368 | I20: =IF('Profit & Loss (Input)'!I4>0,'Balance Sheet (Input)'!I17/('Profit & Loss (Input)'!I4/365),0) -> 63.227837 | ... K20: =IF('Profit & Loss (Input)'!K4>0,'Balance Sheet (Input)'!K17/('Profit & Loss (Input)'!K4/365),0) -> 69.775262
A21: Inventory Turnover | B21: =IF('Balance Sheet (Input)'!B18>0,'Profit & Loss (Input)'!B4/'Balance Sheet (Input)'!B18,0) -> 0 | C21: =IF('Balance Sheet (Input)'!C18>0,'Profit & Loss (Input)'!C4/'Balance Sheet (Input)'!C18,0) -> 0 | D21: =IF('Balance Sheet (Input)'!D18>0,'Profit & Loss (Input)'!D4/'Balance Sheet (Input)'!D18,0) -> 0 | E21: =IF('Balance Sheet (Input)'!E18>0,'Profit & Loss (Input)'!E4/'Balance Sheet (Input)'!E18,0) -> 0 | F21: =IF('Balance Sheet (Input)'!F18>0,'Profit & Loss (Input)'!F4/'Balance Sheet (Input)'!F18,0) -> 0 | G21: =IF('Balance Sheet (Input)'!G18>0,'Profit & Loss (Input)'!G4/'Balance Sheet (Input)'!G18,0) -> 0 | H21: =IF('Balance Sheet (Input)'!H18>0,'Profit & Loss (Input)'!H4/'Balance Sheet (Input)'!H18,0) -> 0 | I21: =IF('Balance Sheet (Input)'!I18>0,'Profit & Loss (Input)'!I4/'Balance Sheet (Input)'!I18,0) -> 0 | ... K21: =IF('Balance Sheet (Input)'!K18>0,'Profit & Loss (Input)'!K4/'Balance Sheet (Input)'!K18,0) -> 0
A23: Return on Equity | B23: =IF(SUM('Balance Sheet (Input)'!B4:B5)>0,'Profit & Loss (Input)'!B12/SUM('Balance Sheet (Input)'!B4:B5),"") -> 0.21846657 | C23: =IF(SUM('Balance Sheet (Input)'!C4:C5)>0,'Profit & Loss (Input)'!C12/SUM('Balance Sheet (Input)'!C4:C5),"") -> 0.20806877 | D23: =IF(SUM('Balance Sheet (Input)'!D4:D5)>0,'Profit & Loss (Input)'!D12/SUM('Balance Sheet (Input)'!D4:D5),"") -> 0.24689247 | E23: =IF(SUM('Balance Sheet (Input)'!E4:E5)>0,'Profit & Loss (Input)'!E12/SUM('Balance Sheet (Input)'!E4:E5),"") -> 0.23717435 | F23: =IF(SUM('Balance Sheet (Input)'!F4:F5)>0,'Profit & Loss (Input)'!F12/SUM('Balance Sheet (Input)'!F4:F5),"") -> 0.25353705 | G23: =IF(SUM('Balance Sheet (Input)'!G4:G5)>0,'Profit & Loss (Input)'!G12/SUM('Balance Sheet (Input)'!G4:G5),"") -> 0.25344789 | H23: =IF(SUM('Balance Sheet (Input)'!H4:H5)>0,'Profit & Loss (Input)'!H12/SUM('Balance Sheet (Input)'!H4:H5),"") -> 0.29343066 | I23: =IF(SUM('Balance Sheet (Input)'!I4:I5)>0,'Profit & Loss (Input)'!I12/SUM('Balance Sheet (Input)'!I4:I5),"") -> 0.31953267 | ... K23: =IF(SUM('Balance Sheet (Input)'!K4:K5)>0,'Profit & Loss (Input)'!K12/SUM('Balance Sheet (Input)'!K4:K5),"") -> 0.27878895
A24: Return on Capital Emp | C24: =IF((B4+B5+B6+C4+C5+C6)>0,('Profit & Loss (Input)'!C10+'Profit & Loss (Input)'!C9)*2/(B4+B5+B6+C4+C5+C6),"") -> 0.30523385 | D24: =IF((C4+C5+C6+D4+D5+D6)>0,('Profit & Loss (Input)'!D10+'Profit & Loss (Input)'!D9)*2/(C4+C5+C6+D4+D5+D6),"") -> 0.30275195 | E24: =IF((D4+D5+D6+E4+E5+E6)>0,('Profit & Loss (Input)'!E10+'Profit & Loss (Input)'!E9)*2/(D4+D5+D6+E4+E5+E6),"") -> 0.32402923 | F24: =IF((E4+E5+E6+F4+F5+F6)>0,('Profit & Loss (Input)'!F10+'Profit & Loss (Input)'!F9)*2/(E4+E5+E6+F4+F5+F6),"") -> 0.32847272 | G24: =IF((F4+F5+F6+G4+G5+G6)>0,('Profit & Loss (Input)'!G10+'Profit & Loss (Input)'!G9)*2/(F4+F5+F6+G4+G5+G6),"") -> 0.35349469 | H24: =IF((G4+G5+G6+H4+H5+H6)>0,('Profit & Loss (Input)'!H10+'Profit & Loss (Input)'!H9)*2/(G4+G5+G6+H4+H5+H6),"") -> 0.37304615 | I24: =IF((H4+H5+H6+I4+I5+I6)>0,('Profit & Loss (Input)'!I10+'Profit & Loss (Input)'!I9)*2/(H4+H5+H6+I4+I5+I6),"") -> 0.40850909 | J24: =IF((I4+I5+I6+J4+J5+J6)>0,('Profit & Loss (Input)'!J10+'Profit & Loss (Input)'!J9)*2/(I4+I5+I6+J4+J5+J6),"") -> 0.40468196 | K24: =IF((J4+J5+J6+K4+K5+K6)>0,('Profit & Loss (Input)'!K10+'Profit & Loss (Input)'!K9)*2/(J4+J5+J6+K4+K5+K6),"") -> 0.37925394

Sheet Cash flow data (Input)
I4: 42795 | J4: 43160 | K4: 43525 | L4: 43891 | M4: 44256 | N4: 44621 | O4: 44986 | P4: 45352 | Q4: 45717
E5: Cash from Operating Activity - | I5: 11531 | J5: 13218 | K5: 14841 | L5: 17003 | M5: 23224 | N5: 23885 | O5: 22467 | P5: 25210 | Q5: 35694
E6: Profit from operations | I6: 19340 | J6: 19963 | K6: 22126 | L6: 23920 | M6: 28845 | N6: 32921 | O6: 37605 | P6: 39523 | Q6: 41591
E7: Receivables | I7: -1743 | J7: -1523 | K7: -2881 | L7: -3861 | M7: -1835 | N7: -7937 | O7: -7076 | P7: -2667 | Q7: -1769
E8: Payables | I8: -19 | J8: 328 | K8: 916 | L8: -373 | M8: -245 | N8: 1489 | O8: -279 | P8: 91 | Q8: 176
E9: Loans Advances | I9: 0 | J9: 0 | K9: 0 | L9: 0 | M9: -534 | N9: -1914 | O9: -3108 | P9: -1172 | Q9: -1024
E10: Other WC items | I10: -394 | J10: 1279 | K10: 1512 | L10: 1867 | M10: 3382 | N10: 6938 | O10: 4119 | P10: -1334 | Q10: 2322
E11: Working capital changes | I11: -2156 | J11: 84 | K11: -453 | L11: -2367 | M11: 768 | N11: -1424 | O11: -6344 | P11: -5082 | Q11: -295
E12: Direct taxes | I12: -5653 | J12: -6829 | K12: -6832 | L12: -4550 | M12: -6389 | N12: -7612 | O12: -8794 | P12: -9231 | Q12: -5602
E13: Cash from Investing Activity - | I13: -14664 | J13: 4533 | K13: -632 | L13: -331 | M13: -7373 | N13: -6485 | O13: -1071 | P13: -5093 | Q13: -1864
E14: Fixed assets purchased | I14: -2760 | J14: -1998 | K14: -2445 | L14: -3307 | M14: -2107 | N14: -2161 | O14: -2579 | P14: -2201 | Q14: -2237
E15: Fixed assets sold | I15: 0 | J15: 0 | K15: 0 | L15: 0 | M15: 0 | N15: 0 | O15: 0 | P15: 0 | Q15: 0
E16: Investments purchased | I16: -66410 | J16: -69159 | K16: -79410 | L16: -37482 | M16: -46738 | N16: -59951 | O16: -75800 | P16: -78118 | Q16: -82753
... E29: Net Cash Flow | I29: -10072 | J29: -2754 | K29: -303 | L29: -919 | M29: 6065 | N29: -7242 | O29: -5299 | P29: 2613 | Q29: 9669

Sheet 3 Statement Model
B2: Historical Financial Statements - INFOSYS LTD
B3: Years | C3: ='Data (Input)'!C16 -> 42825 | D3: ='Data (Input)'!D16 -> 43190 | E3: ='Data (Input)'!E16 -> 43555 | F3: ='Data (Input)'!F16 -> 43921 | G3: ='Data (Input)'!G16 -> 44286 | H3: ='Data (Input)'!H16 -> 44651 | I3: ='Data (Input)'!I16 -> 45016 | J3: ='Data (Input)'!J16 -> 45382 | K3: ='Data (Input)'!K16 -> 45747 | L3: LTM
A5: # | B5: Income Statement
B7: Sales | C7: =IFERROR('Data (Input)'!C17,0) -> 68484 | D7: =IFERROR('Data (Input)'!D17,0) -> 70522 | E7: =IFERROR('Data (Input)'!E17,0) -> 82675 | F7: =IFERROR('Data (Input)'!F17,0) -> 90791 | G7: =IFERROR('Data (Input)'!G17,0) -> 100472 | H7: =IFERROR('Data (Input)'!H17,0) -> 121641 | I7: =IFERROR('Data (Input)'!I17,0) -> 146767 | J7: =IFERROR('Data (Input)'!J17,0) -> 153670 | K7: =IFERROR('Data (Input)'!K17,0) -> 162990 | L7: =IFERROR(SUM('Data (Input)'!H42:K42),0) -> 173173
B8: Sales Growth % | C8: - | D8: =D7/C7-1 -> 0.029758776 | E8: =E7/D7-1 -> 0.1723292 | F8: =F7/E7-1 -> 0.098167523 | G8: =G7/F7-1 -> 0.10662951 | H8: =H7/G7-1 -> 0.21069552 | I8: =I7/H7-1 -> 0.20655864 | J8: =J7/I7-1 -> 0.047033734 | K8: =K7/J7-1 -> 0.060649444 | L8: =L7/K7-1 -> 0.062476226
B10: COGS | C10: =IFERROR(SUM('Data (Input)'!C20:C22),0) -> 44609 | D10: =IFERROR(SUM('Data (Input)'!D20:D22),0) -> 46395 | E10: =IFERROR(SUM('Data (Input)'!E20:E22),0) -> 55446 | F10: =IFERROR(SUM('Data (Input)'!F20:F22),0) -> 62210 | G10: =IFERROR(SUM('Data (Input)'!G20:G22),0) -> 68490 | H10: =IFERROR(SUM('Data (Input)'!H20:H22),0) -> 84819 | I10: =IFERROR(SUM('Data (Input)'!I20:I22),0) -> 104880 | J10: =IFERROR(SUM('Data (Input)'!J20:J22),0) -> 110030 | K10: =IFERROR(SUM('Data (Input)'!K20:K22),0) -> 116585 | L10: =IFERROR(SUM('Data (Input)'!H43:K43),0) -> 132187
B11: COGS % of Sales | C11: =C10/C7 -> 0.65137842 | D11: =D10/D7 -> 0.65787981 | E11: =E10/E7 -> 0.67065014 | F11: =F10/F7 -> 0.68520007 | G11: =G10/G7 -> 0.68168246 | H11: =H10/H7 -> 0.69728957 | I11: =I10/I7 -> 0.71460206 | J11: =J10/J7 -> 0.71601484 | ... L11: =L10/L7 -> 0.76332338
B13: Gross Profit | C13: =IFERROR(C7-C10,0) -> 23875 | D13: =IFERROR(D7-D10,0) -> 24127 | E13: =IFERROR(E7-E10,0) -> 27229 | F13: =IFERROR(F7-F10,0) -> 28581 | G13: =IFERROR(G7-G10,0) -> 31982 | H13: =IFERROR(H7-H10,0) -> 36822 | I13: =IFERROR(I7-I10,0) -> 41887 | J13: =IFERROR(J7-J10,0) -> 43640 | ... L13: =IFERROR(L7-L10,0) -> 40986
B14: Gross Margins % | C14: =C13/C7 -> 0.34862158 | D14: =D13/D7 -> 0.34212019 | E14: =E13/E7 -> 0.32934986 | F14: =F13/F7 -> 0.31479993 | G14: =G13/G7 -> 0.31831754 | H14: =H13/H7 -> 0.30271043 | I14: =I13/I7 -> 0.28539794 | J14: =J13/J7 -> 0.28398516 | ... L14: =L13/L7 -> 0.23667662
B16: Selling and Gereral expenses | C16: =IFERROR(SUM('Data (Input)'!C23:C24),0) -> 5271 | D16: =IFERROR(SUM('Data (Input)'!D23:D24),0) -> 5305 | E16: =IFERROR(SUM('Data (Input)'!E23:E24),0) -> 7059 | F16: =IFERROR(SUM('Data (Input)'!F23:F24),0) -> 6314 | G16: =IFERROR(SUM('Data (Input)'!G23:G24),0) -> 4093 | H16: =IFERROR(SUM('Data (Input)'!H23:H24),0) -> 5331 | I16: =IFERROR(SUM('Data (Input)'!I23:I24),0) -> 6757 | J16: =IFERROR(SUM('Data (Input)'!J23:J24),0) -> 7215 | K16: =IFERROR(SUM('Data (Input)'!K23:K24),0) -> 7169
B17: S & G Expenses % of Sales | C17: =C16/C7 -> 0.076966883 | D17: =D16/D7 -> 0.075224753 | E17: =E16/E7 -> 0.085382522 | F17: =F16/F7 -> 0.069544338 | G17: =G16/G7 -> 0.040737718 | H17: =H16/H7 -> 0.043825684 | I17: =I16/I7 -> 0.04603896 | J17: =J16/J7 -> 0.046951259 | K17: =K16/K7 -> 0.043984294
B19: EBITDA | C19: =IFERROR(C13-C16,0) -> 18604 | D19: =IFERROR(D13-D16,0) -> 18822 | E19: =IFERROR(E13-E16,0) -> 20170 | F19: =IFERROR(F13-F16,0) -> 22267 | G19: =IFERROR(G13-G16,0) -> 27889 | H19: =IFERROR(H13-H16,0) -> 31491 | I19: =IFERROR(I13-I16,0) -> 35130 | J19: =IFERROR(J13-J16,0) -> 36425 | ... L19: =IFERROR(L13-L16,0) -> 40986
B20: EBITDA % of Sales | C20: =C19/C7 -> 0.27165469 | D20: =D19/D7 -> 0.26689544 | E20: =E19/E7 -> 0.24396734 | F20: =F19/F7 -> 0.24525559 | G20: =G19/G7 -> 0.27757982 | H20: =H19/H7 -> 0.25888475 | I20: =I19/I7 -> 0.23935898 | J20: =J19/J7 -> 0.2370339 | ... L20: =L19/L7 -> 0.23667662
B22: Depreciation | C22: =IFERROR('Data (Input)'!C26,0) -> 1703 | D22: =IFERROR('Data (Input)'!D26,0) -> 1863 | E22: =IFERROR('Data (Input)'!E26,0) -> 2011 | F22: =IFERROR('Data (Input)'!F26,0) -> 2893 | G22: =IFERROR('Data (Input)'!G26,0) -> 3267 | H22: =IFERROR('Data (Input)'!H26,0) -> 3476 | I22: =IFERROR('Data (Input)'!I26,0) -> 4225 | J22: =IFERROR('Data (Input)'!J26,0) -> 4678 | K22: =IFERROR('Data (Input)'!K26,0) -> 4812 | L22: =IFERROR(SUM('Data (Input)'!H45:K45),0) -> 4776
B24: EBIT | C24: =IFERROR(C19-C22,0) -> 16901 | D24: =IFERROR(D19-D22,0) -> 16959 | E24: =IFERROR(E19-E22,0) -> 18159 | F24: =IFERROR(F19-F22,0) -> 19374 | G24: =IFERROR(G19-G22,0) -> 24622 | H24: =IFERROR(H19-H22,0) -> 28015 | I24: =IFERROR(I19-I22,0) -> 30905 | J24: =IFERROR(J19-J22,0) -> 31747 | ... L24: =IFERROR(L19-L22,0) -> 36210
B25: Other Income | C25: =IFERROR('Data (Input)'!C25,0) -> 3050 | D25: =IFERROR('Data (Input)'!D25,0) -> 3311 | E25: =IFERROR('Data (Input)'!E25,0) -> 2882 | F25: =IFERROR('Data (Input)'!F25,0) -> 2803 | G25: =IFERROR('Data (Input)'!G25,0) -> 2201 | H25: =IFERROR('Data (Input)'!H25,0) -> 2295 | I25: =IFERROR('Data (Input)'!I25,0) -> 2701 | J25: =IFERROR('Data (Input)'!J25,0) -> 4711 | K25: =IFERROR('Data (Input)'!K25,0) -> 3600 | L25: =IFERROR(SUM('Data (Input)'!H44:K44),0) -> 3064
B26: Interest | C26: =IFERROR('Data (Input)'!C27,0) -> 0 | D26: =IFERROR('Data (Input)'!D27,0) -> 0 | E26: =IFERROR('Data (Input)'!E27,0) -> 0 | F26: =IFERROR('Data (Input)'!F27,0) -> 170 | G26: =IFERROR('Data (Input)'!G27,0) -> 195 | H26: =IFERROR('Data (Input)'!H27,0) -> 200 | I26: =IFERROR('Data (Input)'!I27,0) -> 284 | J26: =IFERROR('Data (Input)'!J27,0) -> 470 | K26: =IFERROR('Data (Input)'!K27,0) -> 416 | L26: =IFERROR(SUM('Data (Input)'!H46:K46),0) -> 413
B28: EBT | C28: =IFERROR(C24+C25-C26,0) -> 19951 | D28: =IFERROR(D24+D25-D26,0) -> 20270 | E28: =IFERROR(E24+E25-E26,0) -> 21041 | F28: =IFERROR(F24+F25-F26,0) -> 22007 | G28: =IFERROR(G24+G25-G26,0) -> 26628 | H28: =IFERROR(H24+H25-H26,0) -> 30110 | I28: =IFERROR(I24+I25-I26,0) -> 33322 | J28: =IFERROR(J24+J25-J26,0) -> 35988 | ... L28: =IFERROR(L24+L25-L26,0) -> 38861
B30: Tax | C30: =IFERROR('Data (Input)'!C29,0) -> 5598 | D30: =IFERROR('Data (Input)'!D29,0) -> 4241 | E30: =IFERROR('Data (Input)'!E29,0) -> 5631 | F30: =IFERROR('Data (Input)'!F29,0) -> 5368 | G30: =IFERROR('Data (Input)'!G29,0) -> 7205 | H30: =IFERROR('Data (Input)'!H29,0) -> 7964 | I30: =IFERROR('Data (Input)'!I29,0) -> 9214 | J30: =IFERROR('Data (Input)'!J29,0) -> 9740 | K30: =IFERROR('Data (Input)'!K29,0) -> 10858 | L30: =IFERROR(SUM('Data (Input)'!H48:K48),0) -> 10858
B31: Effective Tax Rate | C31: =C30/C28 -> 0.28058744 | D31: =D30/D28 -> 0.20922546 | E31: =E30/E28 -> 0.26762036 | F31: =F30/F28 -> 0.24392239 | G31: =G30/G28 -> 0.27057984 | H31: =H30/H28 -> 0.26449684 | I31: =I30/I28 -> 0.27651401 | J31: =J30/J28 -> 0.27064577 | ... L31: =L30/L28 -> 0.27940609
B33: Net Profit | C33: =IFERROR(C28-C30,0) -> 14353 | D33: =IFERROR(D28-D30,0) -> 16029 | E33: =IFERROR(E28-E30,0) -> 15410 | F33: =IFERROR(F28-F30,0) -> 16639 | G33: =IFERROR(G28-G30,0) -> 19423 | H33: =IFERROR(H28-H30,0) -> 22146 | I33: =IFERROR(I28-I30,0) -> 24108 | J33: =IFERROR(J28-J30,0) -> 26248 | ... L33: =IFERROR(L28-L30,0) -> 28003
B34: Net Profit % of Sales | C34: =C33/C7 -> 0.2095818 | D34: =D33/D7 -> 0.22729077 | E34: =E33/E7 -> 0.1863925 | F34: =F33/F7 -> 0.18326706 | G34: =G33/G7 -> 0.19331754 | H34: =H33/H7 -> 0.18206033 | I34: =I33/I7 -> 0.16426036 | J34: =J33/J7 -> 0.17080757 | ... L34: =L33/L7 -> 0.16170535
B36: No of Equity Shares | C36: ='Data (Input)'!B93 -> 459.39 | D36: ='Data (Input)'!C93 -> 459.39 | E36: ='Data (Input)'!D93 -> 436.82 | F36: ='Data (Input)'!E93 -> 436.89 | G36: ='Data (Input)'!F93 -> 425.9 | H36: ='Data (Input)'!G93 -> 426.07 | I36: ='Data (Input)'!H93 -> 420.67 | J36: ='Data (Input)'!I93 -> 414.86 | K36: ='Data (Input)'!J93 -> 415.09 | L36: =K36 -> 415.09
B37: Earning Per Share | C37: =C33/C36 -> 31.243606 | D37: =D33/D36 -> 34.891922 | E37: =E33/E36 -> 35.277689 | F37: =F33/F36 -> 38.085102 | G37: =G33/G36 -> 45.604602 | H37: =H33/H36 -> 51.977375 | I37: =I33/I36 -> 57.308579 | J37: =J33/J36 -> 63.269537 | ... L37: =L33/L36 -> 67.462478
B38: EPS Growth % | C38: - | D38: =D37/C37-1 -> 0.11677001 | E38: =E37/D37-1 -> 0.011056051 | F38: =F37/E37-1 -> 0.079580405 | G38: =G37/F37-1 -> 0.19743942 | H38: =H37/G37-1 -> 0.13973968 | I38: =I37/H37-1 -> 0.10256779 | J38: =J37/I37-1 -> 0.1040151 | K38: =K37/J37-1 -> 0.018560573 | L38: =L37/K37-1 -> 0.046841121
B40: Dividend Per Share | C40: ='Data (Input)'!C31/'3 Statement Model'!C36 -> 12.824833 | D40: ='Data (Input)'!D31/'3 Statement Model'!D36 -> 20.604715 | E40: ='Data (Input)'!E31/'3 Statement Model'!E36 -> 21.112815 | F40: ='Data (Input)'!F31/'3 Statement Model'!F36 -> 16.999702 | G40: ='Data (Input)'!G31/'3 Statement Model'!G36 -> 26.930265 | H40: ='Data (Input)'!H31/'3 Statement Model'!H36 -> 30.529256 | I40: ='Data (Input)'!I31/'3 Statement Model'!I36 -> 33.444743 | J40: ='Data (Input)'!J31/'3 Statement Model'!J36 -> 45.926819 | K40: ='Data (Input)'!K31/'3 Statement Model'!K36 -> 42.94924
B41: Dividend Payout Ratio | C41: =C40/C37 -> 0.41047865 | D41: =D40/D37 -> 0.59052966 | E41: =E40/E37 -> 0.59847502 | F41: =F40/F37 -> 0.44636096 | G41: =G40/G37 -> 0.5905164 | H41: =H40/H37 -> 0.58735663 | I41: =I40/I37 -> 0.58359051 | J41: =J40/J37 -> 0.7258915 | K41: =K40/K37 -> 0.66645981
B43: Retained Earnings | C43: =1-C41 -> 0.58952135 | D43: =1-D41 -> 0.40947034 | E43: =1-E41 -> 0.40152498 | F43: =1-F41 -> 0.55363904 | G43: =1-G41 -> 0.4094836 | H43: =1-H41 -> 0.41264337 | I43: =1-I41 -> 0.41640949 | J43: =1-J41 -> 0.2741085 | K43: =1-K41 -> 0.33354019
A45: # | B45: Balance Sheet
B47: Equity Share Capital | C47: ='Balance Sheet (Input)'!C4 -> 1144 | D47: ='Balance Sheet (Input)'!D4 -> 1088 | E47: ='Balance Sheet (Input)'!E4 -> 2170 | F47: ='Balance Sheet (Input)'!F4 -> 2122 | G47: ='Balance Sheet (Input)'!G4 -> 2124 | H47: ='Balance Sheet (Input)'!H4 -> 2098 | I47: ='Balance Sheet (Input)'!I4 -> 2069 | J47: ='Balance Sheet (Input)'!J4 -> 2071 | K47: ='Balance Sheet (Input)'!K4 -> 2073
B48: Reserves | C48: ='Balance Sheet (Input)'!C5 -> 67838 | D48: ='Balance Sheet (Input)'!D5 -> 63835 | E48: ='Balance Sheet (Input)'!E5 -> 62778 | F48: ='Balance Sheet (Input)'!F5 -> 63328 | G48: ='Balance Sheet (Input)'!G5 -> 74227 | H48: ='Balance Sheet (Input)'!H5 -> 73252 | I48: ='Balance Sheet (Input)'!I5 -> 73338 | J48: ='Balance Sheet (Input)'!J5 -> 86045 | K48: ='Balance Sheet (Input)'!K5 -> 93745
B49: Borrowings | C49: ='Balance Sheet (Input)'!C6 -> 0 | D49: ='Balance Sheet (Input)'!D6 -> 0 | E49: ='Balance Sheet (Input)'!E6 -> 0 | F49: ='Balance Sheet (Input)'!F6 -> 4633 | G49: ='Balance Sheet (Input)'!G6 -> 5325 | H49: ='Balance Sheet (Input)'!H6 -> 5474 | I49: ='Balance Sheet (Input)'!I6 -> 8299 | J49: ='Balance Sheet (Input)'!J6 -> 8359 | K49: ='Balance Sheet (Input)'!K6 -> 8227
B50: Other Liabilities | C50: ='Balance Sheet (Input)'!C7 -> 14166 | D50: ='Balance Sheet (Input)'!D7 -> 14426 | E50: ='Balance Sheet (Input)'!E7 -> 19118 | F50: ='Balance Sheet (Input)'!F7 -> 21717 | G50: ='Balance Sheet (Input)'!G7 -> 25835 | H50: ='Balance Sheet (Input)'!H7 -> 35905 | I50: ='Balance Sheet (Input)'!I7 -> 40890 | J50: ='Balance Sheet (Input)'!J7 -> 40885 | K50: ='Balance Sheet (Input)'!K7 -> 43750
B51: Total Liabilities | C51: =SUM(C47:C50) -> 83148 | D51: =SUM(D47:D50) -> 79349 | E51: =SUM(E47:E50) -> 84066 | F51: =SUM(F47:F50) -> 91800 | G51: =SUM(G47:G50) -> 107511 | H51: =SUM(H47:H50) -> 116729 | I51: =SUM(I47:I50) -> 124596 | J51: =SUM(J47:J50) -> 137360 | K51: =SUM(K47:K50) -> 147795
B53: Net Block of Fixed Assets | C53: ='Balance Sheet (Input)'!C10 -> 14179 | D53: ='Balance Sheet (Input)'!D10 -> 12574 | E53: ='Balance Sheet (Input)'!E10 -> 15710 | F53: ='Balance Sheet (Input)'!F10 -> 23789 | G53: ='Balance Sheet (Input)'!G10 -> 25505 | H53: ='Balance Sheet (Input)'!H10 -> 25800 | I53: ='Balance Sheet (Input)'!I10 -> 29225 | J53: ='Balance Sheet (Input)'!J10 -> 27622 | K53: ='Balance Sheet (Input)'!K10 -> 30961
B54: Capital Work in Progress | C54: ='Balance Sheet (Input)'!C11 -> 1365 | D54: ='Balance Sheet (Input)'!D11 -> 1606 | E54: ='Balance Sheet (Input)'!E11 -> 1388 | F54: ='Balance Sheet (Input)'!F11 -> 954 | G54: ='Balance Sheet (Input)'!G11 -> 922 | H54: ='Balance Sheet (Input)'!H11 -> 416 | I54: ='Balance Sheet (Input)'!I11 -> 288 | J54: ='Balance Sheet (Input)'!J11 -> 293 | K54: ='Balance Sheet (Input)'!K11 -> 814
B55: Investments | C55: ='Balance Sheet (Input)'!C12 -> 16423 | D55: ='Balance Sheet (Input)'!D12 -> 12163 | E55: ='Balance Sheet (Input)'!E12 -> 11261 | F55: ='Balance Sheet (Input)'!F12 -> 8792 | G55: ='Balance Sheet (Input)'!G12 -> 14205 | H55: ='Balance Sheet (Input)'!H12 -> 20324 | I55: ='Balance Sheet (Input)'!I12 -> 19478 | J55: ='Balance Sheet (Input)'!J12 -> 24623 | K55: ='Balance Sheet (Input)'!K12 -> 23541
B56: Other Assets | C56: ='Balance Sheet (Input)'!C13 -> 51181 | D56: ='Balance Sheet (Input)'!D13 -> 53006 | E56: ='Balance Sheet (Input)'!E13 -> 55707 | F56: ='Balance Sheet (Input)'!F13 -> 58265 | G56: ='Balance Sheet (Input)'!G13 -> 66879 | H56: ='Balance Sheet (Input)'!H13 -> 70189 | I56: ='Balance Sheet (Input)'!I13 -> 75605 | J56: ='Balance Sheet (Input)'!J13 -> 84822 | K56: ='Balance Sheet (Input)'!K13 -> 92479
B57: Total Assets | C57: =SUM(C53:C56) -> 83148 | D57: =SUM(D53:D56) -> 79349 | E57: =SUM(E53:E56) -> 84066 | F57: =SUM(F53:F56) -> 91800 | G57: =SUM(G53:G56) -> 107511 | H57: =SUM(H53:H56) -> 116729 | I57: =SUM(I53:I56) -> 124596 | J57: =SUM(J53:J56) -> 137360 | K57: =SUM(K53:K56) -> 147795
A63: # | B63: Cash Flow Statement
...

Sheet Ratio Analysis
B2: Ratio Analysis - INFOSYS LTD
B3: Years | C3: 42825 | D3: 43190 | E3: 43555 | F3: 43921 | G3: 44286 | H3: 44651 | I3: 45016 | J3: 45382 | K3: 45747 | L3: Trend | M3: Mean | N3: Median
B5: Sales Growth | C5: ='3 Statement Model'!C8 -> - | D5: =IFERROR('3 Statement Model'!D8,0) -> 0.029758776 | E5: =IFERROR('3 Statement Model'!E8,0) -> 0.1723292 | F5: =IFERROR('3 Statement Model'!F8,0) -> 0.098167523 | G5: =IFERROR('3 Statement Model'!G8,0) -> 0.10662951 | H5: =IFERROR('3 Statement Model'!H8,0) -> 0.21069552 | I5: =IFERROR('3 Statement Model'!I8,0) -> 0.20655864 | J5: =IFERROR('3 Statement Model'!J8,0) -> 0.047033734 | K5: =IFERROR('3 Statement Model'!K8,0) -> 0.060649444 | M5: =IFERROR(AVERAGE(D5:K5),0) -> 0.11647779 | N5: =IFERROR(MEDIAN(D5:K5),0) -> 0.10239852
B6: EBITDA Growth | C6: - | D6: =IFERROR('3 Statement Model'!D19/'3 Statement Model'!C19-1,0) -> 0.01171791 | E6: =IFERROR('3 Statement Model'!E19/'3 Statement Model'!D19-1,0) -> 0.071618319 | F6: =IFERROR('3 Statement Model'!F19/'3 Statement Model'!E19-1,0) -> 0.10396629 | G6: =IFERROR('3 Statement Model'!G19/'3 Statement Model'!F19-1,0) -> 0.25248125 | H6: =IFERROR('3 Statement Model'!H19/'3 Statement Model'!G19-1,0) -> 0.12915486 | I6: =IFERROR('3 Statement Model'!I19/'3 Statement Model'!H19-1,0) -> 0.11555683 | J6: =IFERROR('3 Statement Model'!J19/'3 Statement Model'!I19-1,0) -> 0.03686308 | K6: =IFERROR('3 Statement Model'!K19/'3 Statement Model'!J19-1,0) -> 0.077172272 | M6: =IFERROR(AVERAGE(D6:K6),0) -> 0.099816351 | N6: =IFERROR(MEDIAN(D6:K6),0) -> 0.090569279
B7: EBIT Growth | C7: - | D7: =IFERROR('3 Statement Model'!D24/'3 Statement Model'!C24-1,0) -> 0.0034317496 | E7: =IFERROR('3 Statement Model'!E24/'3 Statement Model'!D24-1,0) -> 0.070758889 | F7: =IFERROR('3 Statement Model'!F24/'3 Statement Model'!E24-1,0) -> 0.066908971 | G7: =IFERROR('3 Statement Model'!G24/'3 Statement Model'!F24-1,0) -> 0.2708785 | H7: =IFERROR('3 Statement Model'!H24/'3 Statement Model'!G24-1,0) -> 0.13780359 | I7: =IFERROR('3 Statement Model'!I24/'3 Statement Model'!H24-1,0) -> 0.10315902 | J7: =IFERROR('3 Statement Model'!J24/'3 Statement Model'!I24-1,0) -> 0.027244782 | K7: =IFERROR('3 Statement Model'!K24/'3 Statement Model'!J24-1,0) -> 0.084322928 | M7: =IFERROR(AVERAGE(D7:K7),0) -> 0.095563554 | N7: =IFERROR(MEDIAN(D7:K7),0) -> 0.077540909
B8: Net Profit Growth | C8: - | D8: =IFERROR('3 Statement Model'!D33/'3 Statement Model'!C33-1,0) -> 0.11677001 | E8: =IFERROR('3 Statement Model'!E33/'3 Statement Model'!D33-1,0) -> -0.038617506 | F8: =IFERROR('3 Statement Model'!F33/'3 Statement Model'!E33-1,0) -> 0.079753407 | G8: =IFERROR('3 Statement Model'!G33/'3 Statement Model'!F33-1,0) -> 0.16731775 | H8: =IFERROR('3 Statement Model'!H33/'3 Statement Model'!G33-1,0) -> 0.14019461 | I8: =IFERROR('3 Statement Model'!I33/'3 Statement Model'!H33-1,0) -> 0.088593877 | J8: =IFERROR('3 Statement Model'!J33/'3 Statement Model'!I33-1,0) -> 0.088767214 | K8: =IFERROR('3 Statement Model'!K33/'3 Statement Model'!J33-1,0) -> 0.019125267 | M8: =IFERROR(AVERAGE(D8:K8),0) -> 0.082738079 | N8: =IFERROR(MEDIAN(D8:K8),0) -> 0.088680546
B9: Dividend Growth | C9: - | D9: =IFERROR('3 Statement Model'!D40/'3 Statement Model'!C40-1,0) -> 0.60662638 | E9: =IFERROR('3 Statement Model'!E40/'3 Statement Model'!D40-1,0) -> 0.024659424 | F9: =IFERROR('3 Statement Model'!F40/'3 Statement Model'!E40-1,0) -> -0.19481594 | G9: =IFERROR('3 Statement Model'!G40/'3 Statement Model'!F40-1,0) -> 0.58416098 | H9: =IFERROR('3 Statement Model'!H40/'3 Statement Model'!G40-1,0) -> 0.13364111 | I9: =IFERROR('3 Statement Model'!I40/'3 Statement Model'!H40-1,0) -> 0.09549814 | J9: =IFERROR('3 Statement Model'!J40/'3 Statement Model'!I40-1,0) -> 0.37321488 | K9: =IFERROR('3 Statement Model'!K40/'3 Statement Model'!J40-1,0) -> -0.064833116 | M9: =IFERROR(AVERAGE(D9:K9),0) -> 0.19476898 | N9: =IFERROR(MEDIAN(D9:K9),0) -> 0.11456962
B11: Gross Margin | C11: =IFERROR('3 Statement Model'!C14,0) -> 0.34862158 | D11: =IFERROR('3 Statement Model'!D14,0) -> 0.34212019 | E11: =IFERROR('3 Statement Model'!E14,0) -> 0.32934986 | F11: =IFERROR('3 Statement Model'!F14,0) -> 0.31479993 | G11: =IFERROR('3 Statement Model'!G14,0) -> 0.31831754 | H11: =IFERROR('3 Statement Model'!H14,0) -> 0.30271043 | I11: =IFERROR('3 Statement Model'!I14,0) -> 0.28539794 | J11: =IFERROR('3 Statement Model'!J14,0) -> 0.28398516 | K11: =IFERROR('3 Statement Model'!K14,0) -> 0.28471072 | M11: =IFERROR(AVERAGE(C11:K11),0) -> 0.31222371 | N11: =IFERROR(MEDIAN(C11:K11),0) -> 0.31479993
B12: EBITDA Margin | C12: =IFERROR('3 Statement Model'!C20,0) -> 0.27165469 | D12: =IFERROR('3 Statement Model'!D20,0) -> 0.26689544 | E12: =IFERROR('3 Statement Model'!E20,0) -> 0.24396734 | F12: =IFERROR('3 Statement Model'!F20,0) -> 0.24525559 | G12: =IFERROR('3 Statement Model'!G20,0) -> 0.27757982 | H12: =IFERROR('3 Statement Model'!H20,0) -> 0.25888475 | I12: =IFERROR('3 Statement Model'!I20,0) -> 0.23935898 | J12: =IFERROR('3 Statement Model'!J20,0) -> 0.2370339 | K12: =IFERROR('3 Statement Model'!K20,0) -> 0.24072642 | M12: =IFERROR(AVERAGE(C12:K12),0) -> 0.25348411 | N12: =IFERROR(MEDIAN(C12:K12),0) -> 0.24525559
B13: EBIT Margin | C13: =IFERROR('3 Statement Model'!C24/'3 Statement Model'!C7,0) -> 0.24678757 | D13: =IFERROR('3 Statement Model'!D24/'3 Statement Model'!D7,0) -> 0.24047815 | E13: =IFERROR('3 Statement Model'!E24/'3 Statement Model'!E7,0) -> 0.21964318 | F13: =IFERROR('3 Statement Model'!F24/'3 Statement Model'!F7,0) -> 0.2133912 | G13: =IFERROR('3 Statement Model'!G24/'3 Statement Model'!G7,0) -> 0.2450633 | H13: =IFERROR('3 Statement Model'!H24/'3 Statement Model'!H7,0) -> 0.23030886 | I13: =IFERROR('3 Statement Model'!I24/'3 Statement Model'!I7,0) -> 0.21057186 | J13: =IFERROR('3 Statement Model'!J24/'3 Statement Model'!J7,0) -> 0.20659205 | K13: =IFERROR('3 Statement Model'!K24/'3 Statement Model'!K7,0) -> 0.21120314 | M13: =IFERROR(AVERAGE(C13:K13),0) -> 0.22489326 | N13: =IFERROR(MEDIAN(C13:K13),0) -> 0.21964318
B14: Net Profit Margin | C14: =IFERROR('3 Statement Model'!C33/'3 Statement Model'!C7,0) -> 0.2095818 | D14: =IFERROR('3 Statement Model'!D33/'3 Statement Model'!D7,0) -> 0.22729077 | E14: =IFERROR('3 Statement Model'!E33/'3 Statement Model'!E7,0) -> 0.1863925 | F14: =IFERROR('3 Statement Model'!F33/'3 Statement Model'!F7,0) -> 0.18326706 | G14: =IFERROR('3 Statement Model'!G33/'3 Statement Model'!G7,0) -> 0.19331754 | H14: =IFERROR('3 Statement Model'!H33/'3 Statement Model'!H7,0) -> 0.18206033 | I14: =IFERROR('3 Statement Model'!I33/'3 Statement Model'!I7,0) -> 0.16426036 | J14: =IFERROR('3 Statement Model'!J33/'3 Statement Model'!J7,0) -> 0.17080757 | K14: =IFERROR('3 Statement Model'!K33/'3 Statement Model'!K7,0) -> 0.1641205 | M14: =IFERROR(AVERAGE(C14:K14),0) -> 0.18678872 | N14: =IFERROR(MEDIAN(C14:K14),0) -> 0.18326706
B16: Sales Expense % of Sales | C16: =IFERROR('3 Statement Model'!C17,0) -> 0.076966883 | D16: =IFERROR('3 Statement Model'!D17,0) -> 0.075224753 | E16: =IFERROR('3 Statement Model'!E17,0) -> 0.085382522 | F16: =IFERROR('3 Statement Model'!F17,0) -> 0.069544338 | G16: =IFERROR('3 Statement Model'!G17,0) -> 0.040737718 | H16: =IFERROR('3 Statement Model'!H17,0) -> 0.043825684 | I16: =IFERROR('3 Statement Model'!I17,0) -> 0.04603896 | J16: =IFERROR('3 Statement Model'!J17,0) -> 0.046951259 | K16: =IFERROR('3 Statement Model'!K17,0) -> 0.043984294 | M16: =IFERROR(AVERAGE(C16:K16),0) -> 0.058739601 | N16: =IFERROR(MEDIAN(C16:K16),0) -> 0.046951259
B17: Depreciation % of Sales | C17: =IFERROR('3 Statement Model'!C22/'3 Statement Model'!C7,0) -> 0.024867122 | D17: =IFERROR('3 Statement Model'!D22/'3 Statement Model'!D7,0) -> 0.026417288 | E17: =IFERROR('3 Statement Model'!E22/'3 Statement Model'!E7,0) -> 0.024324161 | F17: =IFERROR('3 Statement Model'!F22/'3 Statement Model'!F7,0) -> 0.031864392 | G17: =IFERROR('3 Statement Model'!G22/'3 Statement Model'!G7,0) -> 0.032516522 | H17: =IFERROR('3 Statement Model'!H22/'3 Statement Model'!H7,0) -> 0.028575891 | I17: =IFERROR('3 Statement Model'!I22/'3 Statement Model'!I7,0) -> 0.028787125 | J17: =IFERROR('3 Statement Model'!J22/'3 Statement Model'!J7,0) -> 0.030441856 | K17: =IFERROR('3 Statement Model'!K22/'3 Statement Model'!K7,0) -> 0.029523284 | M17: =IFERROR(AVERAGE(C17:K17),0) -> 0.028590849 | N17: =IFERROR(MEDIAN(C17:K17),0) -> 0.028787125
B18: Operating Income % of Sales | C18: =IFERROR('3 Statement Model'!C24/'3 Statement Model'!C7,0) -> 0.24678757 | D18: =IFERROR('3 Statement Model'!D24/'3 Statement Model'!D7,0) -> 0.24047815 | E18: =IFERROR('3 Statement Model'!E24/'3 Statement Model'!E7,0) -> 0.21964318 | F18: =IFERROR('3 Statement Model'!F24/'3 Statement Model'!F7,0) -> 0.2133912 | G18: =IFERROR('3 Statement Model'!G24/'3 Statement Model'!G7,0) -> 0.2450633 | H18: =IFERROR('3 Statement Model'!H24/'3 Statement Model'!H7,0) -> 0.23030886 | I18: =IFERROR('3 Statement Model'!I24/'3 Statement Model'!I7,0) -> 0.21057186 | J18: =IFERROR('3 Statement Model'!J24/'3 Statement Model'!J7,0) -> 0.20659205 | K18: =IFERROR('3 Statement Model'!K24/'3 Statement Model'!K7,0) -> 0.21120314 | M18: =IFERROR(AVERAGE(C18:K18),0) -> 0.22489326 | N18: =IFERROR(MEDIAN(C18:K18),0) -> 0.21964318
B20: Return on Capital Employed | C20: =IFERROR('3 Statement Model'!C24/SUM('3 Statement Model'!C47:C49),0) -> 0.24500594 | D20: =IFERROR('3 Statement Model'!D24/SUM('3 Statement Model'!D47:D49),0) -> 0.26121713 | E20: =IFERROR('3 Statement Model'!E24/SUM('3 Statement Model'!E47:E49),0) -> 0.27959291 | F20: =IFERROR('3 Statement Model'!F24/SUM('3 Statement Model'!F47:F49),0) -> 0.27644365 | G20: =IFERROR('3 Statement Model'!G24/SUM('3 Statement Model'!G47:G49),0) -> 0.30145943 | H20: =IFERROR('3 Statement Model'!H24/SUM('3 Statement Model'!H47:H49),0) -> 0.34661734 | I20: =IFERROR('3 Statement Model'!I24/SUM('3 Statement Model'!I47:I49),0) -> 0.3692089 | J20: =IFERROR('3 Statement Model'!J24/SUM('3 Statement Model'!J47:J49),0) -> 0.32906971 | K20: =IFERROR('3 Statement Model'!K24/SUM('3 Statement Model'!K47:K49),0) -> 0.33085684 | M20: =IFERROR(AVERAGE(C20:K20),0) -> 0.30438576 | N20: =IFERROR(MEDIAN(C20:K20),0) -> 0.30145943
B21: Retained Earnings % | C21: =IFERROR('3 Statement Model'!C43,0) -> 0.58952135 | D21: =IFERROR('3 Statement Model'!D43,0) -> 0.40947034 | E21: =IFERROR('3 Statement Model'!E43,0) -> 0.40152498 | F21: =IFERROR('3 Statement Model'!F43,0) -> 0.55363904 | G21: =IFERROR('3 Statement Model'!G43,0) -> 0.4094836 | H21: =IFERROR('3 Statement Model'!H43,0) -> 0.41264337 | I21: =IFERROR('3 Statement Model'!I43,0) -> 0.41640949 | J21: =IFERROR('3 Statement Model'!J43,0) -> 0.2741085 | K21: =IFERROR('3 Statement Model'!K43,0) -> 0.33354019 | M21: =IFERROR(AVERAGE(C21:K21),0) -> 0.4222601 | N21: =IFERROR(MEDIAN(C21:K21),0) -> 0.4094836
B22: Return on Equity % | C22: =IFERROR('3 Statement Model'!C33/SUM('3 Statement Model'!C47:C48),0) -> 0.20806877 | D22: =IFERROR('3 Statement Model'!D33/SUM('3 Statement Model'!D47:D48),0) -> 0.24689247 | E22: =IFERROR('3 Statement Model'!E33/SUM('3 Statement Model'!E47:E48),0) -> 0.23726674 | F22: =IFERROR('3 Statement Model'!F33/SUM('3 Statement Model'!F47:F48),0) -> 0.2542246 | G22: =IFERROR('3 Statement Model'!G33/SUM('3 Statement Model'!G47:G48),0) -> 0.25439091 | H22: =IFERROR('3 Statement Model'!H33/SUM('3 Statement Model'!H47:H48),0) -> 0.29390843 | I22: =IFERROR('3 Statement Model'!I33/SUM('3 Statement Model'!I47:I48),0) -> 0.31970507 | J22: =IFERROR('3 Statement Model'!J33/SUM('3 Statement Model'!J47:J48),0) -> 0.29788007 | K22: =IFERROR('3 Statement Model'!K33/SUM('3 Statement Model'!K47:K48),0) -> 0.2791751 | M22: =IFERROR(AVERAGE(C22:K22),0) -> 0.26572357 | N22: =IFERROR(MEDIAN(C22:K22),0) -> 0.25439091
B23: Self Sustained Growth Rate | C23: =IFERROR(C21*C22,0) -> 0.12266098 | D23: =IFERROR(D21*D22,0) -> 0.10109514 | E23: =IFERROR(E21*E22,0) -> 0.095268523 | F23: =IFERROR(F21*F22,0) -> 0.14074866 | G23: =IFERROR(G21*G22,0) -> 0.1041689 | H23: =IFERROR(H21*H22,0) -> 0.12127936 | I23: =IFERROR(I21*I22,0) -> 0.13312822 | J23: =IFERROR(J21*J22,0) -> 0.081651459 | K23: =IFERROR(K21*K22,0) -> 0.093116116 | M23: =IFERROR(AVERAGE(C23:K23),0) -> 0.11034638 | N23: =IFERROR(MEDIAN(C23:K23),0) -> 0.1041689
B24: Interest Coverage Ratio | C24: =IFERROR(IF('3 Statement Model'!C26=0,"No Debt",'3 Statement Model'!C24/'3 Statement Model'!C26),0) -> No Debt | D24: =IFERROR(IF('3 Statement Model'!D26=0,"No Debt",'3 Statement Model'!D24/'3 Statement Model'!D26),0) -> No Debt | E24: =IFERROR(IF('3 Statement Model'!E26=0,"No Debt",'3 Statement Model'!E24/'3 Statement Model'!E26),0) -> No Debt | F24: =IFERROR(IF('3 Statement Model'!F26=0,"No Debt",'3 Statement Model'!F24/'3 Statement Model'!F26),0) -> 113.96471 | G24: =IFERROR(IF('3 Statement Model'!G26=0,"No Debt",'3 Statement Model'!G24/'3 Statement Model'!G26),0) -> 126.26667 | H24: =IFERROR(IF('3 Statement Model'!H26=0,"No Debt",'3 Statement Model'!H24/'3 Statement Model'!H26),0) -> 140.075 | I24: =IFERROR(IF('3 Statement Model'!I26=0,"No Debt",'3 Statement Model'!I24/'3 Statement Model'!I26),0) -> 108.82042 | J24: =IFERROR(IF('3 Statement Model'!J26=0,"No Debt",'3 Statement Model'!J24/'3 Statement Model'!J26),0) -> 67.546809 | K24: =IFERROR(IF('3 Statement Model'!K26=0,"No Debt",'3 Statement Model'!K24/'3 Statement Model'!K26),0) -> 82.75 | M24: =IFERROR(AVERAGE(C24:K24),0) -> 106.5706 | N24: =IFERROR(MEDIAN(C24:K24),0) -> 111.39256
B26: Debtor Turnover Ratio | C26: =IFERROR('3 Statement Model'!C7/'3 Statement Model'!C57,0) -> 0.82363977 | D26: =IFERROR('3 Statement Model'!D7/'3 Statement Model'!D57,0) -> 0.88875726 | E26: =IFERROR('3 Statement Model'!E7/'3 Statement Model'!E57,0) -> 0.98345348 | F26: =IFERROR('3 Statement Model'!F7/'3 Statement Model'!F57,0) -> 0.98900871 | G26: =IFERROR('3 Statement Model'!G7/'3 Statement Model'!G57,0) -> 0.93452763 | H26: =IFERROR('3 Statement Model'!H7/'3 Statement Model'!H57,0) -> 1.0420804 | I26: =IFERROR('3 Statement Model'!I7/'3 Statement Model'!I57,0) -> 1.1779431 | J26: =IFERROR('3 Statement Model'!J7/'3 Statement Model'!J57,0) -> 1.1187391 | K26: =IFERROR('3 Statement Model'!K7/'3 Statement Model'!K57,0) -> 1.1028113 | M26: =IFERROR(AVERAGE(C26:K26),0) -> 1.0067734 | N26: =IFERROR(MEDIAN(C26:K26),0) -> 0.98900871
B27: Creditor Turnover Ratio | C27: =IFERROR('3 Statement Model'!C7/'3 Statement Model'!C50,0) -> 4.8343922 | D27: =IFERROR('3 Statement Model'!D7/'3 Statement Model'!D50,0) -> 4.8885346 | E27: =IFERROR('3 Statement Model'!E7/'3 Statement Model'!E50,0) -> 4.3244586 | F27: =IFERROR('3 Statement Model'!F7/'3 Statement Model'!F50,0) -> 4.1806419 | G27: =IFERROR('3 Statement Model'!G7/'3 Statement Model'!G50,0) -> 3.8889878 | H27: =IFERROR('3 Statement Model'!H7/'3 Statement Model'!H50,0) -> 3.3878568 | I27: =IFERROR('3 Statement Model'!I7/'3 Statement Model'!I50,0) -> 3.5893128 | J27: =IFERROR('3 Statement Model'!J7/'3 Statement Model'!J50,0) -> 3.7585912 | K27: =IFERROR('3 Statement Model'!K7/'3 Statement Model'!K50,0) -> 3.7254857 | M27: =IFERROR(AVERAGE(C27:K27),0) -> 4.0642513 | N27: =IFERROR(MEDIAN(C27:K27),0) -> 3.8889878
B28: Fixed Assets Turnover | C28: =IFERROR('3 Statement Model'!C7/'3 Statement Model'!C53,0) -> 4.8299598 | D28: =IFERROR('3 Statement Model'!D7/'3 Statement Model'!D53,0) -> 5.6085573 | E28: =IFERROR('3 Statement Model'!E7/'3 Statement Model'!E53,0) -> 5.2625716 | F28: =IFERROR('3 Statement Model'!F7/'3 Statement Model'!F53,0) -> 3.8165118 | G28: =IFERROR('3 Statement Model'!G7/'3 Statement Model'!G53,0) -> 3.939306 | H28: =IFERROR('3 Statement Model'!H7/'3 Statement Model'!H53,0) -> 4.7147674 | I28: =IFERROR('3 Statement Model'!I7/'3 Statement Model'!I53,0) -> 5.0219675 | J28: =IFERROR('3 Statement Model'!J7/'3 Statement Model'!J53,0) -> 5.5633191 | K28: =IFERROR('3 Statement Model'!K7/'3 Statement Model'!K53,0) -> 5.2643648 | M28: =IFERROR(AVERAGE(C28:K28),0) -> 4.8912584 | N28: =IFERROR(MEDIAN(C28:K28),0) -> 5.0219675
