Workbook
Name UPDATE: 'Data Sheet (Input)'!$E$1

Sheet Profit & Loss (Input)
A1: ='Data Sheet (Input)'!B1 -> ASIAN PAINTS LTD | H1: =UPDATE | M1: SCREENER.IN
A3: Narration | B3: ='Data Sheet (Input)'!B16 -> 42460 | C3: ='Data Sheet (Input)'!C16 -> 42825 | D3: ='Data Sheet (Input)'!D16 -> 43190 | E3: ='Data Sheet (Input)'!E16 -> 43555 | F3: ='Data Sheet (Input)'!F16 -> 43921 | G3: ='Data Sheet (Input)'!G16 -> 44286 | H3: ='Data Sheet (Input)'!H16 -> 44651 | I3: ='Data Sheet (Input)'!I16 -> 45016 | ... K3: ='Data Sheet (Input)'!K16 -> 45747 | L3: Trailing | M3: Best Case | N3: Worst Case
A4: Sales | B4: ='Data Sheet (Input)'!B17 -> 14271.49 | C4: ='Data Sheet (Input)'!C17 -> 15061.99 | D4: ='Data Sheet (Input)'!D17 -> 16824.55 | E4: ='Data Sheet (Input)'!E17 -> 19240.13 | F4: ='Data Sheet (Input)'!F17 -> 20211.25 | G4: ='Data Sheet (Input)'!G17 -> 21712.79 | H4: ='Data Sheet (Input)'!H17 -> 29101.28 | I4: ='Data Sheet (Input)'!I17 -> 34488.59 | ... K4: ='Data Sheet (Input)'!K17 -> 33905.62 | L4: =SUM('Quarters (Input)'!H4:K4) -> 34695.75 | M4: =$K4+M23*K4 -> 35677.265 | N4: =$K4+N23*L4 -> 34714.163
A5: Expenses | B5: =SUM('Data Sheet (Input)'!B18,'Data Sheet (Input)'!B20:B24, -1*'Data Sheet (Input)'!B19) -> 11546.45 | C5: =SUM('Data Sheet (Input)'!C18,'Data Sheet (Input)'!C20:C24, -1*'Data Sheet (Input)'!C19) -> 12068.23 | D5: =SUM('Data Sheet (Input)'!D18,'Data Sheet (Input)'!D20:D24, -1*'Data Sheet (Input)'!D19) -> 13620.54 | E5: =SUM('Data Sheet (Input)'!E18,'Data Sheet (Input)'!E20:E24, -1*'Data Sheet (Input)'!E19) -> 15475.19 | F5: =SUM('Data Sheet (Input)'!F18,'Data Sheet (Input)'!F20:F24, -1*'Data Sheet (Input)'!F19) -> 16049.48 | G5: =SUM('Data Sheet (Input)'!G18,'Data Sheet (Input)'!G20:G24, -1*'Data Sheet (Input)'!G19) -> 16857.19 | H5: =SUM('Data Sheet (Input)'!H18,'Data Sheet (Input)'!H20:H24, -1*'Data Sheet (Input)'!H19) -> 24297.67 | I5: =SUM('Data Sheet (Input)'!I18,'Data Sheet (Input)'!I20:I24, -1*'Data Sheet (Input)'!I19) -> 28228.75 | ... K5: =SUM('Data Sheet (Input)'!K18,'Data Sheet (Input)'!K20:K24, -1*'Data Sheet (Input)'!K19) -> 27899.41 | L5: =SUM('Quarters (Input)'!H5:K5) -> 21264.18 | M5: =M4-M6 -> 28860.077 | N5: =N4-N6 -> 28365.285
A6: Operating Profit | B6: =B4-B5 -> 2725.04 | C6: =C4-C5 -> 2993.76 | D6: =D4-D5 -> 3204.01 | E6: =E4-E5 -> 3764.94 | F6: =F4-F5 -> 4161.77 | G6: =G4-G5 -> 4855.6 | H6: =H4-H5 -> 4803.61 | I6: =I4-I5 -> 6259.84 | ... K6: =K4-K5 -> 6006.21 | L6: =SUM('Quarters (Input)'!H6:K6) -> 6345.51 | M6: =M4*M24 -> 6817.1883 | N6: =N4*N24 -> 6348.8776
A7: Other Income | B7: ='Data Sheet (Input)'!B25 -> 213.39 | C7: ='Data Sheet (Input)'!C25 -> 337.9 | D7: ='Data Sheet (Input)'!D25 -> 336.41 | E7: ='Data Sheet (Input)'!E25 -> 273.77 | F7: ='Data Sheet (Input)'!F25 -> 350.1 | G7: ='Data Sheet (Input)'!G25 -> 331.65 | H7: ='Data Sheet (Input)'!H25 -> 295.88 | I7: ='Data Sheet (Input)'!I25 -> 431.46 | ... K7: ='Data Sheet (Input)'!K25 -> 350.22 | L7: =SUM('Quarters (Input)'!H7:K7) -> 475.13 | M7: 0 | N7: 0
A8: Depreciation | B8: ='Data Sheet (Input)'!B26 -> 275.58 | C8: ='Data Sheet (Input)'!C26 -> 334.79 | D8: ='Data Sheet (Input)'!D26 -> 360.47 | E8: ='Data Sheet (Input)'!E26 -> 622.14 | F8: ='Data Sheet (Input)'!F26 -> 780.5 | G8: ='Data Sheet (Input)'!G26 -> 791.27 | H8: ='Data Sheet (Input)'!H26 -> 816.36 | I8: ='Data Sheet (Input)'!I26 -> 858.02 | ... K8: ='Data Sheet (Input)'!K26 -> 1026.34 | L8: =SUM('Quarters (Input)'!H8:K8) -> 1219.97 | M8: =+$L8 -> 1219.97 | N8: =+$L8 -> 1219.97
A9: Interest | B9: ='Data Sheet (Input)'!B27 -> 49 | C9: ='Data Sheet (Input)'!C27 -> 37.33 | D9: ='Data Sheet (Input)'!D27 -> 41.47 | E9: ='Data Sheet (Input)'!E27 -> 110.47 | F9: ='Data Sheet (Input)'!F27 -> 102.33 | G9: ='Data Sheet (Input)'!G27 -> 91.63 | H9: ='Data Sheet (Input)'!H27 -> 95.41 | I9: ='Data Sheet (Input)'!I27 -> 144.45 | ... K9: ='Data Sheet (Input)'!K27 -> 227.02 | L9: =SUM('Quarters (Input)'!H9:K9) -> 189.1 | M9: =+$L9 -> 189.1 | N9: =+$L9 -> 189.1
A10: Profit before tax | B10: ='Data Sheet (Input)'!B28 -> 2613.85 | C10: ='Data Sheet (Input)'!C28 -> 2959.54 | D10: ='Data Sheet (Input)'!D28 -> 3138.48 | E10: ='Data Sheet (Input)'!E28 -> 3306.1 | F10: ='Data Sheet (Input)'!F28 -> 3629.04 | G10: ='Data Sheet (Input)'!G28 -> 4304.35 | H10: ='Data Sheet (Input)'!H28 -> 4187.72 | I10: ='Data Sheet (Input)'!I28 -> 5688.83 | ... K10: ='Data Sheet (Input)'!K28 -> 5103.07 | L10: =SUM('Quarters (Input)'!H10:K10) -> 5411.57 | M10: =M6+M7-SUM(M8:M9) -> 5408.1183 | N10: =N6+N7-SUM(N8:N9) -> 4939.8076
A11: Tax | B11: ='Data Sheet (Input)'!B29 -> 844.49 | C11: ='Data Sheet (Input)'!C29 -> 943.29 | D11: ='Data Sheet (Input)'!D29 -> 1040.96 | E11: ='Data Sheet (Input)'!E29 -> 1098.06 | F11: ='Data Sheet (Input)'!F29 -> 854.85 | G11: ='Data Sheet (Input)'!G29 -> 1097.6 | H11: ='Data Sheet (Input)'!H29 -> 1102.91 | I11: ='Data Sheet (Input)'!I29 -> 1493.5 | ... K11: ='Data Sheet (Input)'!K29 -> 1393.36 | L11: =SUM('Quarters (Input)'!H11:K11) -> 1501.54 | M11: =IF($L10>0,$L11/$L10,0) -> 0.27746846 | N11: =IF($L10>0,$L11/$L10,0) -> 0.27746846
A12: Net profit | B12: ='Data Sheet (Input)'!B30 -> 1745.16 | C12: ='Data Sheet (Input)'!C30 -> 1939.43 | D12: ='Data Sheet (Input)'!D30 -> 2038.93 | E12: ='Data Sheet (Input)'!E30 -> 2155.92 | F12: ='Data Sheet (Input)'!F30 -> 2705.17 | G12: ='Data Sheet (Input)'!G30 -> 3139.29 | H12: ='Data Sheet (Input)'!H30 -> 3030.57 | I12: ='Data Sheet (Input)'!I30 -> 4106.45 | ... K12: ='Data Sheet (Input)'!K30 -> 3667.23 | L12: =SUM('Quarters (Input)'!H12:K12) -> 3845.36 | M12: =M10-M11*M10 -> 3907.536 | N12: =N10-N11*N10 -> 3569.1668
A13: EPS | B13: =IF('Data Sheet (Input)'!B93>0,B12/'Data Sheet (Input)'!B93,0) -> 18.193912 | C13: =IF('Data Sheet (Input)'!C93>0,C12/'Data Sheet (Input)'!C93,0) -> 20.219245 | D13: =IF('Data Sheet (Input)'!D93>0,D12/'Data Sheet (Input)'!D93,0) -> 21.256568 | E13: =IF('Data Sheet (Input)'!E93>0,E12/'Data Sheet (Input)'!E93,0) -> 22.47623 | F13: =IF('Data Sheet (Input)'!F93>0,F12/'Data Sheet (Input)'!F93,0) -> 28.202356 | G13: =IF('Data Sheet (Input)'!G93>0,G12/'Data Sheet (Input)'!G93,0) -> 32.728211 | H13: =IF('Data Sheet (Input)'!H93>0,H12/'Data Sheet (Input)'!H93,0) -> 31.594766 | I13: =IF('Data Sheet (Input)'!I93>0,I12/'Data Sheet (Input)'!I93,0) -> 42.811197 | ... K13: =IF('Data Sheet (Input)'!K93>0,K12/'Data Sheet (Input)'!K93,0) -> 38.232173 | L13: =IF('Data Sheet (Input)'!$B6>0,'Profit & Loss (Input)'!L12/'Data Sheet (Input)'!$B6,0) -> 40.089326 | M13: =IF('Data Sheet (Input)'!$B6>0,'Profit & Loss (Input)'!M12/'Data Sheet (Input)'!$B6,0) -> 40.737534 | N13: =IF('Data Sheet (Input)'!$B6>0,'Profit & Loss (Input)'!N12/'Data Sheet (Input)'!$B6,0) -> 37.209907
A14: Price to earning | B14: =IF(B15>0,B15/B13,"") -> 47.730253 | C14: =IF(C15>0,C15/C13,"") -> 53.092981 | D14: =IF(D15>0,D15/D13,"") -> 52.708415 | E14: =IF(E15>0,E15/E13,"") -> 66.412383 | F14: =IF(F15>0,F15/F13,"") -> 59.090808 | G14: =IF(G15>0,G15/G13,"") -> 77.529444 | H14: =IF(H15>0,H15/H13,"") -> 97.482917 | I14: =IF(I15>0,I15/I13,"") -> 64.507657 | ... K14: =IF(K15>0,K15/K13,"") -> 61.221998 | L14: =IF(L13>0,L15/L13,0) -> 55.401281 | M14: =M25 -> 57.784967 | N14: =N25 -> 55.401281
A15: Price | B15: ='Data Sheet (Input)'!B90 -> 868.4 | C15: ='Data Sheet (Input)'!C90 -> 1073.5 | D15: ='Data Sheet (Input)'!D90 -> 1120.4 | E15: ='Data Sheet (Input)'!E90 -> 1492.7 | F15: ='Data Sheet (Input)'!F90 -> 1666.5 | G15: ='Data Sheet (Input)'!G90 -> 2537.4 | H15: ='Data Sheet (Input)'!H90 -> 3079.95 | I15: ='Data Sheet (Input)'!I90 -> 2761.65 | ... K15: ='Data Sheet (Input)'!K90 -> 2340.65 | L15: ='Data Sheet (Input)'!B8 -> 2221 | M15: =M13*M14 -> 2354.017 | N15: =N13*N14 -> 2061.4765
A17: RATIOS:
A18: Dividend Payout | B18: =IF('Data Sheet (Input)'!B30>0, 'Data Sheet (Input)'!B31/'Data Sheet (Input)'!B30, 0) -> 0.41222581 | C18: =IF('Data Sheet (Input)'!C30>0, 'Data Sheet (Input)'!C31/'Data Sheet (Input)'!C30, 0) -> 0.50941772 | D18: =IF('Data Sheet (Input)'!D30>0, 'Data Sheet (Input)'!D31/'Data Sheet (Input)'!D30, 0) -> 0.4092833 | E18: =IF('Data Sheet (Input)'!E30>0, 'Data Sheet (Input)'!E31/'Data Sheet (Input)'!E30, 0) -> 0.46716019 | F18: =IF('Data Sheet (Input)'!F30>0, 'Data Sheet (Input)'!F31/'Data Sheet (Input)'!F30, 0) -> 0.42549636 | G18: =IF('Data Sheet (Input)'!G30>0, 'Data Sheet (Input)'!G31/'Data Sheet (Input)'!G30, 0) -> 0.54540039 | H18: =IF('Data Sheet (Input)'!H30>0, 'Data Sheet (Input)'!H31/'Data Sheet (Input)'!H30, 0) -> 0.6061137 | I18: =IF('Data Sheet (Input)'!I30>0, 'Data Sheet (Input)'!I31/'Data Sheet (Input)'!I30, 0) -> 0.59914281 | ... K18: =IF('Data Sheet (Input)'!K30>0, 'Data Sheet (Input)'!K31/'Data Sheet (Input)'!K30, 0) -> 0.64866943
A19: OPM | B19: =IF(B6>0,B6/B4,0) -> 0.19094292 | C19: =IF(C6>0,C6/C4,0) -> 0.19876258 | D19: =IF(D6>0,D6/D4,0) -> 0.19043659 | E19: =IF(E6>0,E6/E4,0) -> 0.19568163 | F19: =IF(F6>0,F6/F4,0) -> 0.20591354 | G19: =IF(G6>0,G6/G4,0) -> 0.22362856 | H19: =IF(H6>0,H6/H4,0) -> 0.16506525 | I19: =IF(I6>0,I6/I4,0) -> 0.18150467 | ... L19: =IF(L6>0,L6/L4,0) -> 0.18289012
G22: TRENDS: | H22: 10 YEARS | I22: 7 YEARS | J22: 5 YEARS | K22: 3 YEARS | L22: RECENT | M22: BEST | N22: WORST
G23: Sales Growth | H23: =IF(B4=0,"",POWER($K4/B4,1/9)-1) -> 0.10092015 | I23: =IF(D4=0,"",POWER($K4/D4,1/7)-1) -> 0.10528802 | J23: =IF(F4=0,"",POWER($K4/F4,1/5)-1) -> 0.10901062 | K23: =IF(H4=0,"",POWER($K4/H4, 1/3)-1) -> 0.052252258 | L23: =IF(ISERROR(MAX(IF(J4=0,"",(K4-J4)/J4),IF(K4=0,"",(L4-K4)/K4))),"",MAX(IF(J4=0,"",(K4-J4)/J4),IF(K4=0,"",(L4-K4)/K4))) -> 0.023303806 | M23: =MAX(K23:L23) -> 0.052252258 | N23: =MIN(H23:L23) -> 0.023303806
G24: OPM | H24: =IF(SUM(B4:$K$4)=0,"",SUMPRODUCT(B19:$K$19,B4:$K$4)/SUM(B4:$K$4)) -> 0.19291454 | I24: =IF(SUM(E4:$K$4)=0,"",SUMPRODUCT(E19:$K$19,E4:$K$4)/SUM(E4:$K$4)) -> 0.19282052 | J24: =IF(SUM(G4:$K$4)=0,"",SUMPRODUCT(G19:$K$19,G4:$K$4)/SUM(G4:$K$4)) -> 0.19075414 | K24: =IF(SUM(I4:$K$4)=0, "", SUMPRODUCT(I19:$K$19,I4:$K$4)/SUM(I4:$K$4)) -> 0.19107934 | L24: =L19 -> 0.18289012 | M24: =MAX(K24:L24) -> 0.19107934 | N24: =MIN(H24:L24) -> 0.18289012
G25: Price to Earning | H25: =IF(ISERROR(AVERAGEIF(B14:$L14,">0")),"",AVERAGEIF(B14:$L14,">0")) -> 62.289733 | I25: =IF(ISERROR(AVERAGEIF(E14:$L14,">0")),"",AVERAGEIF(E14:$L14,">0")) -> 66.456927 | J25: =IF(ISERROR(AVERAGEIF(G14:$L14,">0")),"",AVERAGEIF(G14:$L14,">0")) -> 67.692038 | K25: =IF(ISERROR(AVERAGEIF(I14:$L14,">0")),"",AVERAGEIF(I14:$L14,">0")) -> 57.784967 | L25: =L14 -> 55.401281 | M25: =MAX(K25:L25) -> 57.784967 | N25: =MIN(H25:L25) -> 55.401281

Sheet Quarters (Input)
A1: ='Profit & Loss (Input)'!A1 -> ASIAN PAINTS LTD | E1: =UPDATE | J1: SCREENER.IN
A3: Narration | B3: ='Data Sheet (Input)'!B41 -> 45199 | C3: ='Data Sheet (Input)'!C41 -> 45291 | D3: ='Data Sheet (Input)'!D41 -> 45382 | E3: ='Data Sheet (Input)'!E41 -> 45473 | F3: ='Data Sheet (Input)'!F41 -> 45565 | G3: ='Data Sheet (Input)'!G41 -> 45657 | H3: ='Data Sheet (Input)'!H41 -> 45747 | I3: ='Data Sheet (Input)'!I41 -> 45838 | ... K3: ='Data Sheet (Input)'!K41 -> 46022
A4: Sales | B4: ='Data Sheet (Input)'!B42 -> 8478.57 | C4: ='Data Sheet (Input)'!C42 -> 9103.09 | D4: ='Data Sheet (Input)'!D42 -> 8730.76 | E4: ='Data Sheet (Input)'!E42 -> 8969.73 | F4: ='Data Sheet (Input)'!F42 -> 8027.54 | G4: ='Data Sheet (Input)'!G42 -> 8549.44 | H4: ='Data Sheet (Input)'!H42 -> 8358.91 | I4: ='Data Sheet (Input)'!I42 -> 8938.55 | ... K4: ='Data Sheet (Input)'!K42 -> 8867.02
A5: Expenses | B5: ='Data Sheet (Input)'!B43 -> 6762.34 | C5: ='Data Sheet (Input)'!C43 -> 7047 | D5: ='Data Sheet (Input)'!D43 -> 7039.39 | E5: ='Data Sheet (Input)'!E43 -> 7275.96 | F5: ='Data Sheet (Input)'!F43 -> 6788.03 | G5: ='Data Sheet (Input)'!G43 -> 6912.71 | H5: ='Data Sheet (Input)'!H43 -> 6922.71 | I5: ='Data Sheet (Input)'!I43 -> 7313.58 | J5: ='Data Sheet (Input)'!J43 -> 7027.89 | K5: (
A6: Operating Profit | B6: ='Data Sheet (Input)'!B50 -> 1716.23 | C6: ='Data Sheet (Input)'!C50 -> 2056.09 | D6: ='Data Sheet (Input)'!D50 -> 1691.37 | E6: ='Data Sheet (Input)'!E50 -> 1693.77 | F6: ='Data Sheet (Input)'!F50 -> 1239.51 | G6: ='Data Sheet (Input)'!G50 -> 1636.73 | H6: ='Data Sheet (Input)'!H50 -> 1436.2 | I6: ='Data Sheet (Input)'!I50 -> 1624.97 | ... K6: ='Data Sheet (Input)'!K50 -> 1780.96
A7: Other Income | B7: ='Data Sheet (Input)'!B44 -> 194.33 | C7: ='Data Sheet (Input)'!C44 -> 186.46 | D7: ='Data Sheet (Input)'!D44 -> 212.43 | E7: ='Data Sheet (Input)'!E44 -> 192.93 | F7: ='Data Sheet (Input)'!F44 -> 24.53 | G7: ='Data Sheet (Input)'!G44 -> 192.82 | H7: ='Data Sheet (Input)'!H44 -> -60.06 | I7: ='Data Sheet (Input)'!I44 -> 229.11 | ... K7: ='Data Sheet (Input)'!K44 -> 69.14
A8: Depreciation | B8: ='Data Sheet (Input)'!B45 -> 208.72 | C8: ='Data Sheet (Input)'!C45 -> 220.35 | D8: ='Data Sheet (Input)'!D45 -> 225.61 | E8: ='Data Sheet (Input)'!E45 -> 227.7 | F8: ='Data Sheet (Input)'!F45 -> 241.99 | G8: ='Data Sheet (Input)'!G45 -> 255.55 | H8: ='Data Sheet (Input)'!H45 -> 301.1 | I8: ='Data Sheet (Input)'!I45 -> 300.87 | ... K8: ='Data Sheet (Input)'!K45 -> 313.07
A9: Interest | B9: ='Data Sheet (Input)'!B46 -> 50.9 | C9: ='Data Sheet (Input)'!C46 -> 54.42 | D9: ='Data Sheet (Input)'!D46 -> 54.1 | E9: ='Data Sheet (Input)'!E46 -> 55.38 | F9: ='Data Sheet (Input)'!F46 -> 63.01 | G9: ='Data Sheet (Input)'!G46 -> 55.84 | H9: ='Data Sheet (Input)'!H46 -> 52.79 | I9: ='Data Sheet (Input)'!I46 -> 44.5 | ... K9: ='Data Sheet (Input)'!K46 -> 47.94
A10: Profit before tax | B10: ='Data Sheet (Input)'!B47 -> 1650.94 | C10: ='Data Sheet (Input)'!C47 -> 1967.78 | D10: ='Data Sheet (Input)'!D47 -> 1624.09 | E10: ='Data Sheet (Input)'!E47 -> 1603.62 | F10: ='Data Sheet (Input)'!F47 -> 959.04 | G10: ='Data Sheet (Input)'!G47 -> 1518.16 | H10: ='Data Sheet (Input)'!H47 -> 1022.25 | I10: ='Data Sheet (Input)'!I47 -> 1508.71 | ... K10: ='Data Sheet (Input)'!K47 -> 1489.09
A11: Tax | B11: ='Data Sheet (Input)'!B48 -> 418.55 | C11: ='Data Sheet (Input)'!C48 -> 492.62 | D11: ='Data Sheet (Input)'!D48 -> 348.79 | E11: ='Data Sheet (Input)'!E48 -> 416.83 | F11: ='Data Sheet (Input)'!F48 -> 265.38 | G11: ='Data Sheet (Input)'!G48 -> 389.73 | H11: ='Data Sheet (Input)'!H48 -> 321.42 | I11: ='Data Sheet (Input)'!I48 -> 391.66 | ... K11: ='Data Sheet (Input)'!K48 -> 415.17
A12: Net profit | B12: ='Data Sheet (Input)'!B49 -> 1205.42 | C12: ='Data Sheet (Input)'!C49 -> 1447.72 | D12: ='Data Sheet (Input)'!D49 -> 1256.72 | E12: ='Data Sheet (Input)'!E49 -> 1169.98 | F12: ='Data Sheet (Input)'!F49 -> 694.64 | G12: ='Data Sheet (Input)'!G49 -> 1110.48 | H12: ='Data Sheet (Input)'!H49 -> 692.13 | I12: ='Data Sheet (Input)'!I49 -> 1099.77 | ... K12: ='Data Sheet (Input)'!K49 -> 1059.87
A14: OPM | B14: =IF(B4>0,B6/B4,"") -> 0.20241975 | C14: =IF(C4>0,C6/C4,"") -> 0.22586726 | D14: =IF(D4>0,D6/D4,"") -> 0.1937254 | E14: =IF(E4>0,E6/E4,"") -> 0.18883177 | F14: =IF(F4>0,F6/F4,"") -> 0.1544072 | G14: =IF(G4>0,G6/G4,"") -> 0.19144295 | H14: =IF(H4>0,H6/H4,"") -> 0.17181666 | I14: =IF(I4>0,I6/I4,"") -> 0.18179347 | ... K14: =IF(K4>0,K6/K4,"") -> 0.20085215

Sheet Balance Sheet (Input)
A1: ='Profit & Loss (Input)'!A1 -> ASIAN PAINTS LTD | E1: =UPDATE | J1: SCREENER.IN
A3: Narration | B3: ='Data Sheet (Input)'!B56 -> 42460 | C3: ='Data Sheet (Input)'!C56 -> 42825 | D3: ='Data Sheet (Input)'!D56 -> 43190 | E3: ='Data Sheet (Input)'!E56 -> 43555 | F3: ='Data Sheet (Input)'!F56 -> 43921 | G3: ='Data Sheet (Input)'!G56 -> 44286 | H3: ='Data Sheet (Input)'!H56 -> 44651 | I3: ='Data Sheet (Input)'!I56 -> 45016 | ... K3: ='Data Sheet (Input)'!K56 -> 45747
A4: Equity Share Capital | B4: ='Data Sheet (Input)'!B57 -> 95.92 | C4: ='Data Sheet (Input)'!C57 -> 95.92 | D4: ='Data Sheet (Input)'!D57 -> 95.92 | E4: ='Data Sheet (Input)'!E57 -> 95.92 | F4: ='Data Sheet (Input)'!F57 -> 95.92 | G4: ='Data Sheet (Input)'!G57 -> 95.92 | H4: ='Data Sheet (Input)'!H57 -> 95.92 | I4: ='Data Sheet (Input)'!I57 -> 95.92 | ... K4: ='Data Sheet (Input)'!K57 -> 95.92
A5: Reserves | B5: ='Data Sheet (Input)'!B58 -> 6428.9 | C5: ='Data Sheet (Input)'!C58 -> 7507.97 | D5: ='Data Sheet (Input)'!D58 -> 8314.31 | E5: ='Data Sheet (Input)'!E58 -> 9374.63 | F5: ='Data Sheet (Input)'!F58 -> 10034.24 | G5: ='Data Sheet (Input)'!G58 -> 12710.37 | H5: ='Data Sheet (Input)'!H58 -> 13715.64 | I5: ='Data Sheet (Input)'!I58 -> 15896.31 | ... K5: ='Data Sheet (Input)'!K58 -> 19303.89
A6: Borrowings | B6: ='Data Sheet (Input)'!B59 -> 323.29 | C6: ='Data Sheet (Input)'!C59 -> 560.34 | D6: ='Data Sheet (Input)'!D59 -> 533.43 | E6: ='Data Sheet (Input)'!E59 -> 1319.6 | F6: ='Data Sheet (Input)'!F59 -> 1118.5 | G6: ='Data Sheet (Input)'!G59 -> 1093.12 | H6: ='Data Sheet (Input)'!H59 -> 1586.88 | I6: ='Data Sheet (Input)'!I59 -> 1932.62 | ... K6: ='Data Sheet (Input)'!K59 -> 2290.29
A7: Other Liabilities | B7: ='Data Sheet (Input)'!B60 -> 3710.92 | C7: ='Data Sheet (Input)'!C60 -> 4240.96 | D7: ='Data Sheet (Input)'!D60 -> 4819.82 | E7: ='Data Sheet (Input)'!E60 -> 5458.69 | F7: ='Data Sheet (Input)'!F60 -> 4889.31 | G7: ='Data Sheet (Input)'!G60 -> 6455.93 | H7: ='Data Sheet (Input)'!H60 -> 7559.99 | I7: ='Data Sheet (Input)'!I60 -> 7854.48 | ... K7: ='Data Sheet (Input)'!K60 -> 8665.15
A8: Total | B8: ='Data Sheet (Input)'!B61 -> 10559.03 | C8: ='Data Sheet (Input)'!C61 -> 12405.19 | D8: ='Data Sheet (Input)'!D61 -> 13763.48 | E8: ='Data Sheet (Input)'!E61 -> 16248.84 | F8: ='Data Sheet (Input)'!F61 -> 16137.97 | G8: ='Data Sheet (Input)'!G61 -> 20355.34 | H8: ='Data Sheet (Input)'!H61 -> 22958.43 | I8: ='Data Sheet (Input)'!I61 -> 25779.33 | ... K8: ='Data Sheet (Input)'!K61 -> 30355.25
A10: Net Block | B10: ='Data Sheet (Input)'!B62 -> 3416.35 | C10: ='Data Sheet (Input)'!C62 -> 3303.74 | D10: ='Data Sheet (Input)'!D62 -> 3732.24 | E10: ='Data Sheet (Input)'!E62 -> 6496.56 | F10: ='Data Sheet (Input)'!F62 -> 6272.31 | G10: ='Data Sheet (Input)'!G62 -> 5858.52 | H10: ='Data Sheet (Input)'!H62 -> 5519.06 | I10: ='Data Sheet (Input)'!I62 -> 5770.46 | ... K10: ='Data Sheet (Input)'!K62 -> 9220.1
A11: Capital Work in Progress | B11: ='Data Sheet (Input)'!B63 -> 106.59 | C11: ='Data Sheet (Input)'!C63 -> 257.54 | D11: ='Data Sheet (Input)'!D63 -> 1405.11 | E11: ='Data Sheet (Input)'!E63 -> 209.67 | F11: ='Data Sheet (Input)'!F63 -> 140.24 | G11: ='Data Sheet (Input)'!G63 -> 182.98 | H11: ='Data Sheet (Input)'!H63 -> 426.43 | I11: ='Data Sheet (Input)'!I63 -> 1019.59 | ... K11: ='Data Sheet (Input)'!K63 -> 1254.49
A12: Investments | B12: ='Data Sheet (Input)'!B64 -> 2712.13 | C12: ='Data Sheet (Input)'!C64 -> 2651.99 | D12: ='Data Sheet (Input)'!D64 -> 2140.7 | E12: ='Data Sheet (Input)'!E64 -> 2568.58 | F12: ='Data Sheet (Input)'!F64 -> 2018.85 | G12: ='Data Sheet (Input)'!G64 -> 4736.8 | H12: ='Data Sheet (Input)'!H64 -> 3247.53 | I12: ='Data Sheet (Input)'!I64 -> 4261.71 | ... K12: ='Data Sheet (Input)'!K64 -> 4724.75
A13: Other Assets | B13: ='Data Sheet (Input)'!B65 -> 4323.96 | C13: ='Data Sheet (Input)'!C65 -> 6191.92 | D13: ='Data Sheet (Input)'!D65 -> 6485.43 | E13: ='Data Sheet (Input)'!E65 -> 6974.03 | F13: ='Data Sheet (Input)'!F65 -> 7706.57 | G13: ='Data Sheet (Input)'!G65 -> 9577.04 | H13: ='Data Sheet (Input)'!H65 -> 13765.41 | I13: ='Data Sheet (Input)'!I65 -> 14727.57 | ... K13: ='Data Sheet (Input)'!K65 -> 15155.91
A14: Total | B14: ='Data Sheet (Input)'!B66 -> 10559.03 | C14: ='Data Sheet (Input)'!C66 -> 12405.19 | D14: ='Data Sheet (Input)'!D66 -> 13763.48 | E14: ='Data Sheet (Input)'!E66 -> 16248.84 | F14: ='Data Sheet (Input)'!F66 -> 16137.97 | G14: ='Data Sheet (Input)'!G66 -> 20355.34 | H14: ='Data Sheet (Input)'!H66 -> 22958.43 | I14: ='Data Sheet (Input)'!I66 -> 25779.33 | ... K14: ='Data Sheet (Input)'!K66 -> 30355.25
A16: Working Capital | B16: =B13-B7 -> 613.04 | C16: =C13-C7 -> 1950.96 | D16: =D13-D7 -> 1665.61 | E16: =E13-E7 -> 1515.34 | F16: =F13-F7 -> 2817.26 | G16: =G13-G7 -> 3121.11 | H16: =H13-H7 -> 6205.42 | I16: =I13-I7 -> 6873.09 | ... K16: =K13-K7 -> 6490.76
A17: Debtors | B17: ='Data Sheet (Input)'!B67 -> 1186.84 | C17: ='Data Sheet (Input)'!C67 -> 1446.6 | D17: ='Data Sheet (Input)'!D67 -> 1730.63 | E17: ='Data Sheet (Input)'!E67 -> 1907.33 | F17: ='Data Sheet (Input)'!F67 -> 1795.22 | G17: ='Data Sheet (Input)'!G67 -> 2602.17 | H17: ='Data Sheet (Input)'!H67 -> 3871.44 | I17: ='Data Sheet (Input)'!I67 -> 4636.94 | ... K17: ='Data Sheet (Input)'!K67 -> 4313.65
A18: Inventory | B18: ='Data Sheet (Input)'!B68 -> 1998.24 | C18: ='Data Sheet (Input)'!C68 -> 2626.94 | D18: ='Data Sheet (Input)'!D68 -> 2658.31 | E18: ='Data Sheet (Input)'!E68 -> 3149.86 | F18: ='Data Sheet (Input)'!F68 -> 3389.81 | G18: ='Data Sheet (Input)'!G68 -> 3798.6 | H18: ='Data Sheet (Input)'!H68 -> 6152.98 | I18: ='Data Sheet (Input)'!I68 -> 6210.64 | ... K18: ='Data Sheet (Input)'!K68 -> 6719.27
A20: Debtor Days | B20: =IF('Profit & Loss (Input)'!B4>0,'Balance Sheet (Input)'!B17/('Profit & Loss (Input)'!B4/365),0) -> 30.353985 | C20: =IF('Profit & Loss (Input)'!C4>0,'Balance Sheet (Input)'!C17/('Profit & Loss (Input)'!C4/365),0) -> 35.055726 | D20: =IF('Profit & Loss (Input)'!D4>0,'Balance Sheet (Input)'!D17/('Profit & Loss (Input)'!D4/365),0) -> 37.545132 | E20: =IF('Profit & Loss (Input)'!E4>0,'Balance Sheet (Input)'!E17/('Profit & Loss (Input)'!E4/365),0) -> 36.183511 | F20: =IF('Profit & Loss (Input)'!F4>0,'Balance Sheet (Input)'!F17/('Profit & Loss (Input)'!F4/365),0) -> 32.420325 | G20: =IF('Profit & Loss (Input)'!G4>0,'Balance Sheet (Input)'!G17/('Profit & Loss (Input)'!G4/365),0) -> 43.743436 | H20: =IF('Profit & Loss (Input)'!H4>0,'Balance Sheet (Input)'!H17/('Profit & Loss (Input)'!H4/365),0) -> 48.557163 | I20: =IF('Profit & Loss (Input)'!I4>0,'Balance Sheet (Input)'!I17/('Profit & Loss (Input)'!I4/365),0) -> 49.073711 | ... K20: =IF('Profit & Loss (Input)'!K4>0,'Balance Sheet (Input)'!K17/('Profit & Loss (Input)'!K4/365),0) -> 46.437206
A21: Inventory Turnover | B21: =IF('Balance Sheet (Input)'!B18>0,'Profit & Loss (Input)'!B4/'Balance Sheet (Input)'!B18,0) -> 7.14203 | C21: =IF('Balance Sheet (Input)'!C18>0,'Profit & Loss (Input)'!C4/'Balance Sheet (Input)'!C18,0) -> 5.7336635 | D21: =IF('Balance Sheet (Input)'!D18>0,'Profit & Loss (Input)'!D4/'Balance Sheet (Input)'!D18,0) -> 6.3290399 | E21: =IF('Balance Sheet (Input)'!E18>0,'Profit & Loss (Input)'!E4/'Balance Sheet (Input)'!E18,0) -> 6.1082493 | F21: =IF('Balance Sheet (Input)'!F18>0,'Profit & Loss (Input)'!F4/'Balance Sheet (Input)'!F18,0) -> 5.9623548 | G21: =IF('Balance Sheet (Input)'!G18>0,'Profit & Loss (Input)'!G4/'Balance Sheet (Input)'!G18,0) -> 5.715998 | H21: =IF('Balance Sheet (Input)'!H18>0,'Profit & Loss (Input)'!H4/'Balance Sheet (Input)'!H18,0) -> 4.7296237 | I21: =IF('Balance Sheet (Input)'!I18>0,'Profit & Loss (Input)'!I4/'Balance Sheet (Input)'!I18,0) -> 5.5531459 | ... K21: =IF('Balance Sheet (Input)'!K18>0,'Profit & Loss (Input)'!K4/'Balance Sheet (Input)'!K18,0) -> 5.0460273
A23: Return on Equity | B23: =IF(SUM('Balance Sheet (Input)'!B4:B5)>0,'Profit & Loss (Input)'!B12/SUM('Balance Sheet (Input)'!B4:B5),"") -> 0.26746485 | C23: =IF(SUM('Balance Sheet (Input)'!C4:C5)>0,'Profit & Loss (Input)'!C12/SUM('Balance Sheet (Input)'!C4:C5),"") -> 0.25505761 | D23: =IF(SUM('Balance Sheet (Input)'!D4:D5)>0,'Profit & Loss (Input)'!D12/SUM('Balance Sheet (Input)'!D4:D5),"") -> 0.24243451 | E23: =IF(SUM('Balance Sheet (Input)'!E4:E5)>0,'Profit & Loss (Input)'!E12/SUM('Balance Sheet (Input)'!E4:E5),"") -> 0.22764465 | F23: =IF(SUM('Balance Sheet (Input)'!F4:F5)>0,'Profit & Loss (Input)'!F12/SUM('Balance Sheet (Input)'!F4:F5),"") -> 0.26704119 | G23: =IF(SUM('Balance Sheet (Input)'!G4:G5)>0,'Profit & Loss (Input)'!G12/SUM('Balance Sheet (Input)'!G4:G5),"") -> 0.24513657 | H23: =IF(SUM('Balance Sheet (Input)'!H4:H5)>0,'Profit & Loss (Input)'!H12/SUM('Balance Sheet (Input)'!H4:H5),"") -> 0.21942272 | I23: =IF(SUM('Balance Sheet (Input)'!I4:I5)>0,'Profit & Loss (Input)'!I12/SUM('Balance Sheet (Input)'!I4:I5),"") -> 0.25677782 | ... K23: =IF(SUM('Balance Sheet (Input)'!K4:K5)>0,'Profit & Loss (Input)'!K12/SUM('Balance Sheet (Input)'!K4:K5),"") -> 0.18903433
A24: Return on Capital Emp | C24: =IF((B4+B5+B6+C4+C5+C6)>0,('Profit & Loss (Input)'!C10+'Profit & Loss (Input)'!C9)*2/(B4+B5+B6+C4+C5+C6),"") -> 0.39925421 | D24: =IF((C4+C5+C6+D4+D5+D6)>0,('Profit & Loss (Input)'!D10+'Profit & Loss (Input)'!D9)*2/(C4+C5+C6+D4+D5+D6),"") -> 0.37175245 | E24: =IF((D4+D5+D6+E4+E5+E6)>0,('Profit & Loss (Input)'!E10+'Profit & Loss (Input)'!E9)*2/(D4+D5+D6+E4+E5+E6),"") -> 0.34626562 | F24: =IF((E4+E5+E6+F4+F5+F6)>0,('Profit & Loss (Input)'!F10+'Profit & Loss (Input)'!F9)*2/(E4+E5+E6+F4+F5+F6),"") -> 0.3386181 | G24: =IF((F4+F5+F6+G4+G5+G6)>0,('Profit & Loss (Input)'!G10+'Profit & Loss (Input)'!G9)*2/(F4+F5+F6+G4+G5+G6),"") -> 0.34960774 | H24: =IF((G4+G5+G6+H4+H5+H6)>0,('Profit & Loss (Input)'!H10+'Profit & Loss (Input)'!H9)*2/(G4+G5+G6+H4+H5+H6),"") -> 0.29238528 | I24: =IF((H4+H5+H6+I4+I5+I6)>0,('Profit & Loss (Input)'!I10+'Profit & Loss (Input)'!I9)*2/(H4+H5+H6+I4+I5+I6),"") -> 0.35010229 | J24: =IF((I4+I5+I6+J4+J5+J6)>0,('Profit & Loss (Input)'!J10+'Profit & Loss (Input)'!J9)*2/(I4+I5+I6+J4+J5+J6),"") -> 0.38606781 | K24: (

Sheet Cash Flow (Input)
A1: ='Balance Sheet (Input)'!A1 -> ASIAN PAINTS LTD | E1: =UPDATE | J1: SCREENER.IN
A3: Narration | B3: ='Data Sheet (Input)'!B81 -> 42460 | C3: ='Data Sheet (Input)'!C81 -> 42825 | D3: ='Data Sheet (Input)'!D81 -> 43190 | E3: ='Data Sheet (Input)'!E81 -> 43555 | F3: ='Data Sheet (Input)'!F81 -> 43921 | G3: ='Data Sheet (Input)'!G81 -> 44286 | H3: ='Data Sheet (Input)'!H81 -> 44651 | I3: ='Data Sheet (Input)'!I81 -> 45016 | ... K3: ='Data Sheet (Input)'!K81 -> 45747
A4: Cash from Operating Activity | B4: ='Data Sheet (Input)'!B82 -> 2242.95 | C4: ='Data Sheet (Input)'!C82 -> 1527.33 | D4: ='Data Sheet (Input)'!D82 -> 2113.44 | E4: ='Data Sheet (Input)'!E82 -> 2469.54 | F4: ='Data Sheet (Input)'!F82 -> 3038.15 | G4: ='Data Sheet (Input)'!G82 -> 3683.35 | H4: ='Data Sheet (Input)'!H82 -> 986.49 | I4: ='Data Sheet (Input)'!I82 -> 4193.43 | ... K4: ='Data Sheet (Input)'!K82 -> 4423.96
A5: Cash from Investing Activity | B5: ='Data Sheet (Input)'!B83 -> -866.21 | C5: ='Data Sheet (Input)'!C83 -> -681.11 | D5: ='Data Sheet (Input)'!D83 -> -1556.14 | E5: ='Data Sheet (Input)'!E83 -> -917.79 | F5: ='Data Sheet (Input)'!F83 -> -517.91 | G5: ='Data Sheet (Input)'!G83 -> -540.54 | H5: ='Data Sheet (Input)'!H83 -> -316.75 | I5: ='Data Sheet (Input)'!I83 -> -1282.34 | ... K5: ='Data Sheet (Input)'!K83 -> -940.91
A6: Cash from Financing Activity | B6: ='Data Sheet (Input)'!B84 -> -848.98 | C6: ='Data Sheet (Input)'!C84 -> -756.43 | D6: ='Data Sheet (Input)'!D84 -> -1379.14 | E6: ='Data Sheet (Input)'!E84 -> -1117.46 | F6: ='Data Sheet (Input)'!F84 -> -2871.46 | G6: ='Data Sheet (Input)'!G84 -> -650.4 | H6: ='Data Sheet (Input)'!H84 -> -1807.61 | I6: ='Data Sheet (Input)'!I84 -> -2140.05 | ... K6: ='Data Sheet (Input)'!K84 -> -3752.58
A7: Net Cash Flow | B7: ='Data Sheet (Input)'!B85 -> 527.76 | C7: ='Data Sheet (Input)'!C85 -> 89.79 | D7: ='Data Sheet (Input)'!D85 -> -821.84 | E7: ='Data Sheet (Input)'!E85 -> 434.29 | F7: ='Data Sheet (Input)'!F85 -> -351.22 | G7: ='Data Sheet (Input)'!G85 -> 2492.41 | H7: ='Data Sheet (Input)'!H85 -> -1137.87 | I7: ='Data Sheet (Input)'!I85 -> 771.04 | ... K7: ='Data Sheet (Input)'!K85 -> -269.53

Sheet Data Sheet (Input)
A1: COMPANY NAME | B1: ASIAN PAINTS LTD | E1: =IF(B2<>B3, "A NEW VERSION OF THE WORKSHEET IS AVAILABLE", "")
A2: LATEST VERSION | B2: 2.1 | E2: PLEASE DO NOT MAKE ANY CHANGES TO THIS SHEET
A3: CURRENT VERSION | B3: 2.1
A5: META
A6: Number of shares | B6: =IF(B9>0, B9/B8, 0) -> 95.919797
A7: Face Value | B7: 1
A8: Current Price | B8: 2221
A9: Market Capitalization | B9: 213037.87
A15: PROFIT & LOSS
A16: Report Date | B16: 42460 | C16: 42825 | D16: 43190 | E16: 43555 | F16: 43921 | G16: 44286 | H16: 44651 | I16: 45016 | J16: 45382 | K16: 45747
A17: Sales | B17: 14271.49 | C17: 15061.99 | D17: 16824.55 | E17: 19240.13 | F17: 20211.25 | G17: 21712.79 | H17: 29101.28 | I17: 34488.59 | J17: 35494.73 | K17: 33905.62
A18: Raw Material Cost | B18: 6569.83 | C18: 7452.6 | D18: 8128.17 | E18: 9974.4 | F18: 9981.99 | G18: 10425.55 | H18: 17123.25 | I18: 18985.53 | J18: 17410.84 | K18: 17504.51
A19: Change in Inventory | B19: -199.33 | C19: 528.6 | D19: -142.13 | E19: 293.26 | F19: 239.15 | G19: 92.45 | H19: 1324.97 | I19: 309.73 | J19: -363.8 | K19: 205
A20: Power and Fuel | B20: 114.48 | C20: 106.02 | D20: 110.3 | E20: 119.63 | F20: 97.79 | G20: 86.05 | H20: 117.23 | I20: 138.29 | J20: 133.25 | K20: 148.58
A21: Other Mfr. Exp | B21: 1535.22 | C21: 1662.75 | D21: 1691.68 | E21: 1862.35 | F21: 1946.12 | G21: 2068.31 | H21: 2880.45 | I21: 2916.2 | J21: 2767.18 | K21: 2687.4
A22: Employee Cost | B22: 994.98 | C22: 1039.89 | D22: 1121.89 | E22: 1242.69 | F22: 1371.27 | G22: 1547.61 | H22: 1794.61 | I22: 2036.41 | J22: 2334.92 | K22: 2605.78
A23: Selling and admin | B23: 3912.3 | C23: 4364.04 | D23: 2254.92 | E23: 2366.87 | F23: 2311.51 | G23: 2245.69 | H23: 2941.98 | I23: 3500.84 | J23: 3811.86 | K23: 3874.94
A24: Other Expenses | B24: -1779.69 | C24: -2028.47 | D24: 171.45 | E24: 202.51 | F24: 579.95 | G24: 576.43 | H24: 765.12 | I24: 961.21 | J24: 1087.9 | K24: 1283.2
A25: Other Income | B25: 213.39 | C25: 337.9 | D25: 336.41 | E25: 273.77 | F25: 350.1 | G25: 331.65 | H25: 295.88 | I25: 431.46 | J25: 820.96 | K25: 350.22
A26: Depreciation | B26: 275.58 | C26: 334.79 | D26: 360.47 | E26: 622.14 | F26: 780.5 | G26: 791.27 | H26: 816.36 | I26: 858.02 | J26: 853 | K26: 1026.34
A27: Interest | B27: 49 | C27: 37.33 | D27: 41.47 | E27: 110.47 | F27: 102.33 | G27: 91.63 | H27: 95.41 | I27: 144.45 | J27: 205.17 | K27: 227.02
... A31: Dividend Amount | B31: 719.4 | C31: 987.98 | D31: 834.5 | E31: 1007.16 | F31: 1151.04 | G31: 1712.17 | H31: 1836.87 | I31: 2460.35 | J31: 3194.14 | K31: 2378.82
A40: Quarters
A41: Report Date | B41: 45199 | C41: 45291 | D41: 45382 | E41: 45473 | F41: 45565 | G41: 45657 | H41: 45747 | I41: 45838 | J41: 45930 | K41: 46022
A42: Sales | B42: 8478.57 | C42: 9103.09 | D42: 8730.76 | E42: 8969.73 | F42: 8027.54 | G42: 8549.44 | H42: 8358.91 | I42: 8938.55 | J42: 8531.27 | K42: 8867.02
A43: Expenses | B43: 6762.34 | C43: 7047 | D43: 7039.39 | E43: 7275.96 | F43: 6788.03 | G43: 6912.71 | H43: 6922.71 | I43: 7313.58 | J43: 7027.89 | K43: 7086.06
A44: Other Income | B44: 194.33 | C44: 186.46 | D44: 212.43 | E44: 192.93 | F44: 24.53 | G44: 192.82 | H44: -60.06 | I44: 229.11 | J44: 236.94 | K44: 69.14
A45: Depreciation | B45: 208.72 | C45: 220.35 | D45: 225.61 | E45: 227.7 | F45: 241.99 | G45: 255.55 | H45: 301.1 | I45: 300.87 | J45: 304.93 | K45: 313.07
A46: Interest | B46: 50.9 | C46: 54.42 | D46: 54.1 | E46: 55.38 | F46: 63.01 | G46: 55.84 | H46: 52.79 | I46: 44.5 | J46: 43.87 | K46: 47.94
A47: Profit before tax | B47: 1650.94 | C47: 1967.78 | D47: 1624.09 | E47: 1603.62 | F47: 959.04 | G47: 1518.16 | H47: 1022.25 | I47: 1508.71 | J47: 1391.52 | K47: 1489.09
A48: Tax | B48: 418.55 | C48: 492.62 | D48: 348.79 | E48: 416.83 | F48: 265.38 | G48: 389.73 | H48: 321.42 | I48: 391.66 | J48: 373.29 | K48: 415.17
A49: Net profit | B49: 1205.42 | C49: 1447.72 | D49: 1256.72 | E49: 1169.98 | F49: 694.64 | G49: 1110.48 | H49: 692.13 | I49: 1099.77 | J49: 993.59 | K49: 1059.87
A50: Operating Profit | B50: 1716.23 | C50: 2056.09 | D50: 1691.37 | E50: 1693.77 | F50: 1239.51 | G50: 1636.73 | H50: 1436.2 | I50: 1624.97 | J50: 1503.38 | K50: 1780.96
A55: BALANCE SHEET
A56: Report Date | B56: 42460 | C56: 42825 | D56: 43190 | E56: 43555 | F56: 43921 | G56: 44286 | H56: 44651 | I56: 45016 | J56: 45382 | K56: 45747
A57: Equity Share Capital | B57: 95.92 | C57: 95.92 | D57: 95.92 | E57: 95.92 | F57: 95.92 | G57: 95.92 | H57: 95.92 | I57: 95.92 | J57: 95.92 | K57: 95.92
A58: Reserves | B58: 6428.9 | C58: 7507.97 | D58: 8314.31 | E58: 9374.63 | F58: 10034.24 | G58: 12710.37 | H58: 13715.64 | I58: 15896.31 | J58: 18632.38 | K58: 19303.89
A59: Borrowings | B59: 323.29 | C59: 560.34 | D59: 533.43 | E59: 1319.6 | F59: 1118.5 | G59: 1093.12 | H59: 1586.88 | I59: 1932.62 | J59: 2474.38 | K59: 2290.29
A60: Other Liabilities | B60: 3710.92 | C60: 4240.96 | D60: 4819.82 | E60: 5458.69 | F60: 4889.31 | G60: 6455.93 | H60: 7559.99 | I60: 7854.48 | J60: 8698.09 | K60: 8665.15
A61: Total | B61: 10559.03 | C61: 12405.19 | D61: 13763.48 | E61: 16248.84 | F61: 16137.97 | G61: 20355.34 | H61: 22958.43 | I61: 25779.33 | J61: 29900.77 | K61: 30355.25
...

Sheet Cash Flow data (input)
F3: 42430 | G3: 42795 | H3: 43160 | I3: 43525 | J3: 43891 | K3: 44256 | L3: 44621 | M3: 44986 | N3: 45352 | O3: 45717
C4: Cash from Operating Activity - | F4: 2243 | G4: 1527 | H4: 2113 | I4: 2470 | J4: 3038 | K4: 3683 | L4: 986 | M4: 4193 | N4: 6104 | O4: 4424
C5: Profit from operations | F5: 2848 | G5: 3056 | H5: 3274 | I5: 3861 | J5: 4380 | K5: 4970 | L5: 4957 | M5: 6460 | N5: 7929 | O5: 6390
C6: Receivables | F6: -146 | G6: -475 | H6: -483 | I6: -205 | J6: 160 | K6: -1342 | L6: -1326 | M6: -834 | N6: -362 | O6: 282
C7: Inventory | F7: 202 | G7: -629 | H7: -39 | I7: -492 | J7: -251 | K7: -409 | L7: -2354 | M7: -56 | N7: 315 | O7: -805
C8: Payables | F8: 142 | G8: 501 | H8: 442 | I8: 287 | J8: -241 | K8: 1544 | L8: 644 | M8: -539 | N8: 269 | O8: -160
C9: Other WC items | F9: 0 | G9: 0 | H9: 0 | I9: 0 | J9: 0 | K9: 0 | L9: 242 | M9: 657 | N9: -212 | O9: 114
C10: Working capital changes | F10: 198 | G10: -603 | H10: -80 | I10: -410 | J10: -331 | K10: -206 | L10: -2795 | M10: -772 | N10: 10 | O10: -570
C11: Direct taxes | F11: -802 | G11: -925 | H11: -1081 | I11: -982 | J11: -1011 | K11: -1080 | L11: -1176 | M11: -1494 | N11: -1835 | O11: -1396
C12: Cash from Investing Activity - | F12: -866 | G12: -681 | H12: -1556 | I12: -918 | J12: -518 | K12: -541 | L12: -317 | M12: -1282 | N12: -2548 | O12: -941
C13: Fixed assets purchased | F13: -817 | G13: -684 | H13: -1426 | I13: -1151 | J13: -414 | K13: -289 | L13: -551 | M13: -1446 | N13: -2496 | O13: -1830
C14: Fixed assets sold | F14: 15 | G14: 17 | H14: 17 | I14: 17 | J14: 37 | K14: 28 | L14: 40 | M14: 26 | N14: 5 | O14: 10
C15: Investments purchased | F15: -282 | G15: -153 | H15: -320 | I15: -573 | J15: -25 | K15: -140 | L15: 0 | M15: -146 | N15: -212 | O15: -1
... C31: Net Cash Flow | F31: 528 | G31: 90 | H31: -822 | I31: 434 | J31: -351 | K31: 2492 | L31: -1138 | M31: 771 | N31: 573 | O31: -270

Sheet 3 Statement Model
B2: Historical Financial Statements - Asian Paints
B3: Years | C3: ='Data Sheet (Input)'!B16 -> 42460 | D3: ='Data Sheet (Input)'!C16 -> 42825 | E3: ='Data Sheet (Input)'!D16 -> 43190 | F3: ='Data Sheet (Input)'!E16 -> 43555 | G3: ='Data Sheet (Input)'!F16 -> 43921 | H3: ='Data Sheet (Input)'!G16 -> 44286 | I3: ='Data Sheet (Input)'!H16 -> 44651 | J3: ='Data Sheet (Input)'!I16 -> 45016 | ... L3: ='Data Sheet (Input)'!K16 -> 45747 | M3: LTm
A5: # | B5: Income Statement
B6: Revenue From Operations | C6: ='Data Sheet (Input)'!B17 -> 14271.49 | D6: ='Data Sheet (Input)'!C17 -> 15061.99 | E6: ='Data Sheet (Input)'!D17 -> 16824.55 | F6: ='Data Sheet (Input)'!E17 -> 19240.13 | G6: ='Data Sheet (Input)'!F17 -> 20211.25 | H6: ='Data Sheet (Input)'!G17 -> 21712.79 | I6: ='Data Sheet (Input)'!H17 -> 29101.28 | J6: ='Data Sheet (Input)'!I17 -> 34488.59 | ... L6: ='Data Sheet (Input)'!K17 -> 33905.62 | M6: =SUM('Data Sheet (Input)'!H42:K42) -> 34695.75
B7: Revenue Growth | C7: - | D7: =(D6-C6)/C6 -> 0.055390152 | E7: =(E6-D6)/D6 -> 0.11702039 | F7: =(F6-E6)/E6 -> 0.14357472 | G7: =(G6-F6)/F6 -> 0.050473671 | H7: =(H6-G6)/G6 -> 0.074292288 | I7: =(I6-H6)/H6 -> 0.34028285 | J7: =(J6-I6)/I6 -> 0.18512278 | K7: =(K6-J6)/J6 -> 0.029173127 | ... M7: =(M6-L6)/L6 -> 0.023303806
B9: Cost of Goods Sold | C9: =SUM('Data Sheet (Input)'!B18,'Data Sheet (Input)'!B20:B22)-1*'Data Sheet (Input)'!B19 -> 9413.84 | D9: =SUM('Data Sheet (Input)'!C18,'Data Sheet (Input)'!C20:C22)-1*'Data Sheet (Input)'!C19 -> 9732.66 | E9: =SUM('Data Sheet (Input)'!D18,'Data Sheet (Input)'!D20:D22)-1*'Data Sheet (Input)'!D19 -> 11194.17 | F9: =SUM('Data Sheet (Input)'!E18,'Data Sheet (Input)'!E20:E22)-1*'Data Sheet (Input)'!E19 -> 12905.81 | G9: =SUM('Data Sheet (Input)'!F18,'Data Sheet (Input)'!F20:F22)-1*'Data Sheet (Input)'!F19 -> 13158.02 | H9: =SUM('Data Sheet (Input)'!G18,'Data Sheet (Input)'!G20:G22)-1*'Data Sheet (Input)'!G19 -> 14035.07 | I9: =SUM('Data Sheet (Input)'!H18,'Data Sheet (Input)'!H20:H22)-1*'Data Sheet (Input)'!H19 -> 20590.57 | J9: =SUM('Data Sheet (Input)'!I18,'Data Sheet (Input)'!I20:I22)-1*'Data Sheet (Input)'!I19 -> 23766.7 | ... L9: =SUM('Data Sheet (Input)'!K18,'Data Sheet (Input)'!K20:K22)-1*'Data Sheet (Input)'!K19 -> 22741.27 | M9: =SUM('Data Sheet (Input)'!H43:K43) -> 28350.24
B10: COGS % of Sales | C10: =C9/C6 -> 0.65962559 | D10: =D9/D6 -> 0.64617358 | E10: =E9/E6 -> 0.66534736 | F10: =F9/F6 -> 0.67077561 | G10: =G9/G6 -> 0.65102455 | H10: =H9/H6 -> 0.64639643 | I10: =I9/I6 -> 0.7075486 | J10: =J9/J6 -> 0.68911776 | ... M10: =M9/M6 -> 0.81710988
B12: Gross Profit | C12: =C6-C9 -> 4857.65 | D12: =D6-D9 -> 5329.33 | E12: =E6-E9 -> 5630.38 | F12: =F6-F9 -> 6334.32 | G12: =G6-G9 -> 7053.23 | H12: =H6-H9 -> 7677.72 | I12: =I6-I9 -> 8510.71 | J12: =J6-J9 -> 10721.89 | ... M12: =M6-M9 -> 6345.51
B13: Gross Margins | C13: =C12/C6 -> 0.34037441 | D13: =D12/D6 -> 0.35382642 | E13: =E12/E6 -> 0.33465264 | F13: =F12/F6 -> 0.32922439 | G13: =G12/G6 -> 0.34897545 | H13: =H12/H6 -> 0.35360357 | I13: =I12/I6 -> 0.2924514 | J13: =J12/J6 -> 0.31088224 | ... M13: =M12/M6 -> 0.18289012
B15: Selling and General Expenses | C15: =SUM('Data Sheet (Input)'!B23:B24) -> 2132.61 | D15: =SUM('Data Sheet (Input)'!C23:C24) -> 2335.57 | E15: =SUM('Data Sheet (Input)'!D23:D24) -> 2426.37 | F15: =SUM('Data Sheet (Input)'!E23:E24) -> 2569.38 | G15: =SUM('Data Sheet (Input)'!F23:F24) -> 2891.46 | H15: =SUM('Data Sheet (Input)'!G23:G24) -> 2822.12 | I15: =SUM('Data Sheet (Input)'!H23:H24) -> 3707.1 | J15: =SUM('Data Sheet (Input)'!I23:I24) -> 4462.05 | ... L15: =SUM('Data Sheet (Input)'!K23:K24) -> 5158.14
B16: S&G Expenses % of Sales | C16: =C15/C6 -> 0.14943149 | D16: =D15/D6 -> 0.15506384 | E16: =E15/E6 -> 0.14421604 | F16: =F15/F6 -> 0.13354276 | G16: =G15/G6 -> 0.14306191 | H16: =H15/H6 -> 0.12997501 | I16: =I15/I6 -> 0.12738615 | J16: =J15/J6 -> 0.12937757 | ... L16: =L15/L6 -> 0.1521323
B18: EBITDA | C18: =C12-C15 -> 2725.04 | D18: =D12-D15 -> 2993.76 | E18: =E12-E15 -> 3204.01 | F18: =F12-F15 -> 3764.94 | G18: =G12-G15 -> 4161.77 | H18: =H12-H15 -> 4855.6 | I18: =I12-I15 -> 4803.61 | J18: =J12-J15 -> 6259.84 | ... M18: =M12-M15 -> 6345.51
B19: EBITDA Margins | C19: =C18/C6 -> 0.19094292 | D19: =D18/D6 -> 0.19876258 | E19: =E18/E6 -> 0.19043659 | F19: =F18/F6 -> 0.19568163 | G19: =G18/G6 -> 0.20591354 | H19: =H18/H6 -> 0.22362856 | I19: =I18/I6 -> 0.16506525 | J19: =J18/J6 -> 0.18150467 | ... M19: =M18/M6 -> 0.18289012
B20: Depreciation | C20: ='Data Sheet (Input)'!B26 -> 275.58 | D20: ='Data Sheet (Input)'!C26 -> 334.79 | E20: ='Data Sheet (Input)'!D26 -> 360.47 | F20: ='Data Sheet (Input)'!E26 -> 622.14 | G20: ='Data Sheet (Input)'!F26 -> 780.5 | H20: ='Data Sheet (Input)'!G26 -> 791.27 | I20: ='Data Sheet (Input)'!H26 -> 816.36 | J20: ='Data Sheet (Input)'!I26 -> 858.02 | ... L20: ='Data Sheet (Input)'!K26 -> 1026.34 | M20: =SUM('Data Sheet (Input)'!H45:K45) -> 1219.97
B22: EBIT | C22: =C18-C20 -> 2449.46 | D22: =D18-D20 -> 2658.97 | E22: =E18-E20 -> 2843.54 | F22: =F18-F20 -> 3142.8 | G22: =G18-G20 -> 3381.27 | H22: =H18-H20 -> 4064.33 | I22: =I18-I20 -> 3987.25 | J22: =J18-J20 -> 5401.82 | ... M22: =M18-M20 -> 5125.54
B23: Other income | C23: ='Data Sheet (Input)'!B25 -> 213.39 | D23: ='Data Sheet (Input)'!C25 -> 337.9 | E23: ='Data Sheet (Input)'!D25 -> 336.41 | F23: ='Data Sheet (Input)'!E25 -> 273.77 | G23: ='Data Sheet (Input)'!F25 -> 350.1 | H23: ='Data Sheet (Input)'!G25 -> 331.65 | I23: ='Data Sheet (Input)'!H25 -> 295.88 | J23: ='Data Sheet (Input)'!I25 -> 431.46 | ... L23: ='Data Sheet (Input)'!K25 -> 350.22 | M23: =SUM('Data Sheet (Input)'!H44:K44) -> 475.13
B24: Interest | C24: ='Data Sheet (Input)'!B27 -> 49 | D24: ='Data Sheet (Input)'!C27 -> 37.33 | E24: ='Data Sheet (Input)'!D27 -> 41.47 | F24: ='Data Sheet (Input)'!E27 -> 110.47 | G24: ='Data Sheet (Input)'!F27 -> 102.33 | H24: ='Data Sheet (Input)'!G27 -> 91.63 | I24: ='Data Sheet (Input)'!H27 -> 95.41 | J24: ='Data Sheet (Input)'!I27 -> 144.45 | ... L24: ='Data Sheet (Input)'!K27 -> 227.02 | M24: =SUM('Data Sheet (Input)'!H46:K46) -> 189.1
B26: EBT | C26: =C22+C23-C24 -> 2613.85 | D26: =D22+D23-D24 -> 2959.54 | E26: =E22+E23-E24 -> 3138.48 | F26: =F22+F23-F24 -> 3306.1 | G26: =G22+G23-G24 -> 3629.04 | H26: =H22+H23-H24 -> 4304.35 | I26: =I22+I23-I24 -> 4187.72 | J26: =J22+J23-J24 -> 5688.83 | ... M26: =M22+M23-M24 -> 5411.57
B27: EBT Margins | C27: =C26/C6 -> 0.18315186 | D27: =D26/D6 -> 0.19649064 | E27: =E26/E6 -> 0.18654169 | F27: =F26/F6 -> 0.17183356 | G27: =G26/G6 -> 0.17955545 | H27: =H26/H6 -> 0.1982403 | I27: =I26/I6 -> 0.14390157 | J27: =J26/J6 -> 0.16494818 | ... M27: =M26/M6 -> 0.15597213
B29: Taxes | C29: ='Data Sheet (Input)'!B29 -> 844.49 | D29: ='Data Sheet (Input)'!C29 -> 943.29 | E29: ='Data Sheet (Input)'!D29 -> 1040.96 | F29: ='Data Sheet (Input)'!E29 -> 1098.06 | G29: ='Data Sheet (Input)'!F29 -> 854.85 | H29: ='Data Sheet (Input)'!G29 -> 1097.6 | I29: ='Data Sheet (Input)'!H29 -> 1102.91 | J29: ='Data Sheet (Input)'!I29 -> 1493.5 | ... L29: ='Data Sheet (Input)'!K29 -> 1393.36 | M29: =SUM('Data Sheet (Input)'!H48:K48) -> 1501.54
B30: Effective Tax Rate | C30: =C29/C26 -> 0.32308281 | D30: =D29/D26 -> 0.31872859 | E30: =E29/E26 -> 0.33167648 | F30: =F29/F26 -> 0.33213151 | G30: =G29/G26 -> 0.23555816 | H30: =H29/H26 -> 0.25499785 | I30: =I29/I26 -> 0.26336766 | J30: =J29/J26 -> 0.26253201 | ... M30: =M29/M26 -> 0.27746846
B32: Net Profit | C32: =C26-C29 -> 1769.36 | D32: =D26-D29 -> 2016.25 | E32: =E26-E29 -> 2097.52 | F32: =F26-F29 -> 2208.04 | G32: =G26-G29 -> 2774.19 | H32: =H26-H29 -> 3206.75 | I32: =I26-I29 -> 3084.81 | J32: =J26-J29 -> 4195.33 | ... M32: =M26-M29 -> 3910.03
B33: Net Profit Margins | C33: =C32/C6 -> 0.12397865 | D33: =D32/D6 -> 0.13386345 | E33: =E32/E6 -> 0.1246702 | F33: =F32/F6 -> 0.11476222 | G33: =G32/G6 -> 0.13725969 | H33: =H32/H6 -> 0.14768945 | I33: =I32/I6 -> 0.10600255 | J33: =J32/J6 -> 0.121644 | ... M33: =M32/M6 -> 0.11269478
B36: No of Equity Shares | C36: ='Data Sheet (Input)'!B93 -> 95.92 | D36: ='Data Sheet (Input)'!C93 -> 95.92 | E36: ='Data Sheet (Input)'!D93 -> 95.92 | F36: ='Data Sheet (Input)'!E93 -> 95.92 | G36: ='Data Sheet (Input)'!F93 -> 95.92 | H36: ='Data Sheet (Input)'!G93 -> 95.92 | I36: ='Data Sheet (Input)'!H93 -> 95.92 | J36: ='Data Sheet (Input)'!I93 -> 95.92 | ... L36: ='Data Sheet (Input)'!K93 -> 95.92 | M36: =L36 -> 95.92
B37: Earning Per Share | C37: =C32/C36 -> 18.446205 | D37: =D32/D36 -> 21.020121 | E37: =E32/E36 -> 21.867389 | F37: =F32/F36 -> 23.0196 | G37: =G32/G36 -> 28.921914 | H37: =H32/H36 -> 33.431505 | I37: =I32/I36 -> 32.160238 | J37: =J32/J36 -> 43.737802 | ... M37: =M32/M36 -> 40.763449
B38: EPS Growth % | C38: - | D38: =D37/C37-1 -> 0.13953633 | E38: =E37/D37-1 -> 0.040307502 | F38: =F37/E37-1 -> 0.052690797 | G38: =G37/F37-1 -> 0.25640387 | H38: =H37/G37-1 -> 0.15592299 | I38: =I37/H37-1 -> -0.038026039 | J38: =J37/I37-1 -> 0.35999624 | K38: =K37/J37-1 -> 0.3247325 | ... M38: =M37/L37-1 -> 0.05399883
B40: Dividend Per Share | C40: ='Data Sheet (Input)'!B31/'3 Statement Model'!C36 -> 7.5 | D40: ='Data Sheet (Input)'!C31/'3 Statement Model'!D36 -> 10.300042 | E40: ='Data Sheet (Input)'!D31/'3 Statement Model'!E36 -> 8.6999583 | F40: ='Data Sheet (Input)'!E31/'3 Statement Model'!F36 -> 10.5 | G40: ='Data Sheet (Input)'!F31/'3 Statement Model'!G36 -> 12 | H40: ='Data Sheet (Input)'!G31/'3 Statement Model'!H36 -> 17.849979 | I40: ='Data Sheet (Input)'!H31/'3 Statement Model'!I36 -> 19.150021 | J40: ='Data Sheet (Input)'!I31/'3 Statement Model'!J36 -> 25.650021 | ... L40: ='Data Sheet (Input)'!K31/'3 Statement Model'!L36 -> 24.800042
B41: Dividend Payout Ratio | C41: =C40/C37 -> 0.40658769 | D41: =D40/D37 -> 0.49000868 | E41: =E40/E37 -> 0.3978508 | F41: =F40/F37 -> 0.45613304 | G41: =G40/G37 -> 0.4149103 | H41: =H40/H37 -> 0.53392687 | I41: =I40/I37 -> 0.59545645 | J41: =J40/J37 -> 0.5864497 | ... L41: =L40/L37 -> 0.6412415
B42: Retained Earnings % | C42: =1-C41 -> 0.59341231 | D42: =1-D41 -> 0.50999132 | E42: =1-E41 -> 0.6021492 | F42: =1-F41 -> 0.54386696 | G42: =1-G41 -> 0.5850897 | H42: =1-H41 -> 0.46607313 | I42: =1-I41 -> 0.40454355 | J42: =1-J41 -> 0.4135503 | ... L42: =1-L41 -> 0.3587585
A44: # | B44: Balance Sheet
B46: Equity Share Capital | C46: ='Data Sheet (Input)'!B57 -> 95.92 | D46: ='Data Sheet (Input)'!C57 -> 95.92 | E46: ='Data Sheet (Input)'!D57 -> 95.92 | F46: ='Data Sheet (Input)'!E57 -> 95.92 | G46: ='Data Sheet (Input)'!F57 -> 95.92 | H46: ='Data Sheet (Input)'!G57 -> 95.92 | I46: ='Data Sheet (Input)'!H57 -> 95.92 | J46: ='Data Sheet (Input)'!I57 -> 95.92 | ... L46: ='Data Sheet (Input)'!K57 -> 95.92
B47: Reserves | C47: ='Data Sheet (Input)'!B58 -> 6428.9 | D47: ='Data Sheet (Input)'!C58 -> 7507.97 | E47: ='Data Sheet (Input)'!D58 -> 8314.31 | F47: ='Data Sheet (Input)'!E58 -> 9374.63 | G47: ='Data Sheet (Input)'!F58 -> 10034.24 | H47: ='Data Sheet (Input)'!G58 -> 12710.37 | I47: ='Data Sheet (Input)'!H58 -> 13715.64 | J47: ='Data Sheet (Input)'!I58 -> 15896.31 | ... L47: ='Data Sheet (Input)'!K58 -> 19303.89
B48: Borrowings | C48: ='Data Sheet (Input)'!B59 -> 323.29 | D48: ='Data Sheet (Input)'!C59 -> 560.34 | E48: ='Data Sheet (Input)'!D59 -> 533.43 | F48: ='Data Sheet (Input)'!E59 -> 1319.6 | G48: ='Data Sheet (Input)'!F59 -> 1118.5 | H48: ='Data Sheet (Input)'!G59 -> 1093.12 | I48: ='Data Sheet (Input)'!H59 -> 1586.88 | J48: ='Data Sheet (Input)'!I59 -> 1932.62 | ... L48: ='Data Sheet (Input)'!K59 -> 2290.29
B49: Other Liabilities | C49: ='Data Sheet (Input)'!B60 -> 3710.92 | D49: ='Data Sheet (Input)'!C60 -> 4240.96 | E49: ='Data Sheet (Input)'!D60 -> 4819.82 | F49: ='Data Sheet (Input)'!E60 -> 5458.69 | G49: ='Data Sheet (Input)'!F60 -> 4889.31 | H49: ='Data Sheet (Input)'!G60 -> 6455.93 | I49: ='Data Sheet (Input)'!H60 -> 7559.99 | J49: ='Data Sheet (Input)'!I60 -> 7854.48 | ... L49: ='Data Sheet (Input)'!K60 -> 8665.15
B51: Total Liabilities | C51: =SUM(C46:C49) -> 10559.03 | D51: =SUM(D46:D49) -> 12405.19 | E51: =SUM(E46:E49) -> 13763.48 | F51: =SUM(F46:F49) -> 16248.84 | G51: =SUM(G46:G49) -> 16137.97 | H51: =SUM(H46:H49) -> 20355.34 | I51: =SUM(I46:I49) -> 22958.43 | J51: =SUM(J46:J49) -> 25779.33 | ... L51: =SUM(L46:L49) -> 30355.25
B53: Net Block of Fixed Assets | C53: ='Data Sheet (Input)'!B62 -> 3416.35 | D53: ='Data Sheet (Input)'!C62 -> 3303.74 | E53: ='Data Sheet (Input)'!D62 -> 3732.24 | F53: ='Data Sheet (Input)'!E62 -> 6496.56 | G53: ='Data Sheet (Input)'!F62 -> 6272.31 | H53: ='Data Sheet (Input)'!G62 -> 5858.52 | I53: ='Data Sheet (Input)'!H62 -> 5519.06 | J53: ='Data Sheet (Input)'!I62 -> 5770.46 | ... L53: ='Data Sheet (Input)'!K62 -> 9220.1
B54: Capital Work in Progress | C54: ='Data Sheet (Input)'!B63 -> 106.59 | D54: ='Data Sheet (Input)'!C63 -> 257.54 | E54: ='Data Sheet (Input)'!D63 -> 1405.11 | F54: ='Data Sheet (Input)'!E63 -> 209.67 | G54: ='Data Sheet (Input)'!F63 -> 140.24 | H54: ='Data Sheet (Input)'!G63 -> 182.98 | I54: ='Data Sheet (Input)'!H63 -> 426.43 | J54: ='Data Sheet (Input)'!I63 -> 1019.59 | ... L54: ='Data Sheet (Input)'!K63 -> 1254.49
B55: Investments | C55: ='Data Sheet (Input)'!B64 -> 2712.13 | D55: ='Data Sheet (Input)'!C64 -> 2651.99 | E55: ='Data Sheet (Input)'!D64 -> 2140.7 | F55: ='Data Sheet (Input)'!E64 -> 2568.58 | G55: ='Data Sheet (Input)'!F64 -> 2018.85 | H55: ='Data Sheet (Input)'!G64 -> 4736.8 | I55: ='Data Sheet (Input)'!H64 -> 3247.53 | J55: ='Data Sheet (Input)'!I64 -> 4261.71 | ... L55: ='Data Sheet (Input)'!K64 -> 4724.75
B56: Total Non Current Assets | C56: =SUM(C53:C55) -> 6235.07 | D56: =SUM(D53:D55) -> 6213.27 | E56: =SUM(E53:E55) -> 7278.05 | F56: =SUM(F53:F55) -> 9274.81 | G56: =SUM(G53:G55) -> 8431.4 | H56: =SUM(H53:H55) -> 10778.3 | I56: =SUM(I53:I55) -> 9193.02 | J56: =SUM(J53:J55) -> 11051.76 | ... L56: =SUM(L53:L55) -> 15199.34
B58: Receivables | C58: ='Data Sheet (Input)'!B67 -> 1186.84 | D58: ='Data Sheet (Input)'!C67 -> 1446.6 | E58: ='Data Sheet (Input)'!D67 -> 1730.63 | F58: ='Data Sheet (Input)'!E67 -> 1907.33 | G58: ='Data Sheet (Input)'!F67 -> 1795.22 | H58: ='Data Sheet (Input)'!G67 -> 2602.17 | I58: ='Data Sheet (Input)'!H67 -> 3871.44 | J58: ='Data Sheet (Input)'!I67 -> 4636.94 | ... L58: ='Data Sheet (Input)'!K67 -> 4313.65
...

Sheet Ratio Analysis
B2: Ratio Analysis -- Asian Paints
B3: Years | C3: ='3 Statement Model'!C3 -> 42460 | D3: ='3 Statement Model'!D3 -> 42825 | E3: ='3 Statement Model'!E3 -> 43190 | F3: ='3 Statement Model'!F3 -> 43555 | G3: ='3 Statement Model'!G3 -> 43921 | H3: ='3 Statement Model'!H3 -> 44286 | I3: ='3 Statement Model'!I3 -> 44651 | J3: ='3 Statement Model'!J3 -> 45016 | ... L3: ='3 Statement Model'!L3 -> 45747 | M3: Trend | N3: Mean | O3: Median
B5: Revenue Growth | C5: ='3 Statement Model'!C7 -> - | D5: ='3 Statement Model'!D7 -> 0.055390152 | E5: ='3 Statement Model'!E7 -> 0.11702039 | F5: ='3 Statement Model'!F7 -> 0.14357472 | G5: ='3 Statement Model'!G7 -> 0.050473671 | H5: ='3 Statement Model'!H7 -> 0.074292288 | I5: ='3 Statement Model'!I7 -> 0.34028285 | J5: ='3 Statement Model'!J7 -> 0.18512278 | ... L5: ='3 Statement Model'!L7 -> -0.044770308 | N5: =AVERAGE(D5:L5) -> 0.10561774 | O5: =MEDIAN(D5:L5) -> 0.074292288
B6: EBITDA Growth | C6: - | D6: ='3 Statement Model'!D18/'3 Statement Model'!C18-1 -> 0.098611397 | E6: ='3 Statement Model'!E18/'3 Statement Model'!D18-1 -> 0.070229411 | F6: ='3 Statement Model'!F18/'3 Statement Model'!E18-1 -> 0.17507124 | G6: ='3 Statement Model'!G18/'3 Statement Model'!F18-1 -> 0.10540141 | H6: ='3 Statement Model'!H18/'3 Statement Model'!G18-1 -> 0.16671512 | I6: ='3 Statement Model'!I18/'3 Statement Model'!H18-1 -> -0.010707225 | J6: ='3 Statement Model'!J18/'3 Statement Model'!I18-1 -> 0.30315325 | K6: ='3 Statement Model'!K18/'3 Statement Model'!J18-1 -> 0.21168912 | L6: ='3 Statement Model'!L18/'3 Statement Model'!K18-1 -> -0.20814425 | N6: =AVERAGE(D6:L6) -> 0.1013355 | O6: =MEDIAN(D6:L6) -> 0.10540141
B7: EBIT Growth | C7: - | D7: ='3 Statement Model'!D22/'3 Statement Model'!C22-1 -> 0.085533138 | E7: ='3 Statement Model'!E22/'3 Statement Model'!D22-1 -> 0.069414096 | F7: ='3 Statement Model'!F22/'3 Statement Model'!E22-1 -> 0.10524206 | G7: ='3 Statement Model'!G22/'3 Statement Model'!F22-1 -> 0.075878198 | H7: ='3 Statement Model'!H22/'3 Statement Model'!G22-1 -> 0.20201285 | I7: ='3 Statement Model'!I22/'3 Statement Model'!H22-1 -> -0.018964995 | J7: ='3 Statement Model'!J22/'3 Statement Model'!I22-1 -> 0.35477334 | K7: ='3 Statement Model'!K22/'3 Statement Model'!J22-1 -> 0.24624293 | L7: ='3 Statement Model'!L22/'3 Statement Model'!K22-1 -> -0.26026667 | N7: =AVERAGE(D7:L7) -> 0.09554055 | O7: =MEDIAN(D7:L7) -> 0.085533138
B8: Net Profit Growth | C8: - | D8: ='3 Statement Model'!D32/'3 Statement Model'!C32-1 -> 0.13953633 | E8: ='3 Statement Model'!E32/'3 Statement Model'!D32-1 -> 0.040307502 | F8: ='3 Statement Model'!F32/'3 Statement Model'!E32-1 -> 0.052690797 | G8: ='3 Statement Model'!G32/'3 Statement Model'!F32-1 -> 0.25640387 | H8: ='3 Statement Model'!H32/'3 Statement Model'!G32-1 -> 0.15592299 | I8: ='3 Statement Model'!I32/'3 Statement Model'!H32-1 -> -0.038026039 | J8: ='3 Statement Model'!J32/'3 Statement Model'!I32-1 -> 0.35999624 | K8: ='3 Statement Model'!K32/'3 Statement Model'!J32-1 -> 0.3247325 | L8: ='3 Statement Model'!L32/'3 Statement Model'!K32-1 -> -0.33250865 | N8: =AVERAGE(D8:L8) -> 0.10656173 | O8: =MEDIAN(D8:L8) -> 0.13953633
B9: Dividend Growth | C9: - | D9: ='3 Statement Model'!D40/'3 Statement Model'!C40-1 -> 0.37333889 | E9: ='3 Statement Model'!E40/'3 Statement Model'!D40-1 -> -0.15534727 | F9: ='3 Statement Model'!F40/'3 Statement Model'!E40-1 -> 0.20690234 | G9: ='3 Statement Model'!G40/'3 Statement Model'!F40-1 -> 0.14285714 | H9: ='3 Statement Model'!H40/'3 Statement Model'!G40-1 -> 0.48749826 | I9: ='3 Statement Model'!I40/'3 Statement Model'!H40-1 -> 0.072831553 | J9: ='3 Statement Model'!J40/'3 Statement Model'!I40-1 -> 0.33942522 | K9: ='3 Statement Model'!K40/'3 Statement Model'!J40-1 -> 0.29824618 | L9: ='3 Statement Model'!L40/'3 Statement Model'!K40-1 -> -0.25525494 | N9: =AVERAGE(D9:L9) -> 0.16783304 | O9: =MEDIAN(D9:L9) -> 0.20690234
B11: GrossMargin | C11: ='3 Statement Model'!C13 -> 0.34037441 | D11: ='3 Statement Model'!D13 -> 0.35382642 | E11: ='3 Statement Model'!E13 -> 0.33465264 | F11: ='3 Statement Model'!F13 -> 0.32922439 | G11: ='3 Statement Model'!G13 -> 0.34897545 | H11: ='3 Statement Model'!H13 -> 0.35360357 | I11: ='3 Statement Model'!I13 -> 0.2924514 | J11: ='3 Statement Model'!J13 -> 0.31088224 | ... L11: ='3 Statement Model'!L13 -> 0.32927727 | N11: =AVERAGE(C11:L11) -> 0.33450028 | O11: =MEDIAN(C11:L11) -> 0.33751352
B12: EBITDA Margin | C12: ='3 Statement Model'!C19 -> 0.19094292 | D12: ='3 Statement Model'!D19 -> 0.19876258 | E12: ='3 Statement Model'!E19 -> 0.19043659 | F12: ='3 Statement Model'!F19 -> 0.19568163 | G12: ='3 Statement Model'!G19 -> 0.20591354 | H12: ='3 Statement Model'!H19 -> 0.22362856 | I12: ='3 Statement Model'!I19 -> 0.16506525 | J12: ='3 Statement Model'!J19 -> 0.18150467 | ... L12: ='3 Statement Model'!L19 -> 0.17714497 | N12: =AVERAGE(C12:L12) -> 0.19427738 | O12: =MEDIAN(C12:L12) -> 0.19331228
B13: EBT Margin | C13: ='3 Statement Model'!C27 -> 0.18315186 | D13: ='3 Statement Model'!D27 -> 0.19649064 | E13: ='3 Statement Model'!E27 -> 0.18654169 | F13: ='3 Statement Model'!F27 -> 0.17183356 | G13: ='3 Statement Model'!G27 -> 0.17955545 | H13: ='3 Statement Model'!H27 -> 0.1982403 | I13: ='3 Statement Model'!I27 -> 0.14390157 | J13: ='3 Statement Model'!J27 -> 0.16494818 | ... L13: ='3 Statement Model'!L27 -> 0.15050809 | N13: =AVERAGE(C13:L13) -> 0.17821815 | O13: =MEDIAN(C13:L13) -> 0.18135365
B14: Net Profit Margin | C14: ='3 Statement Model'!C33 -> 0.12397865 | D14: ='3 Statement Model'!D33 -> 0.13386345 | E14: ='3 Statement Model'!E33 -> 0.1246702 | F14: ='3 Statement Model'!F33 -> 0.11476222 | G14: ='3 Statement Model'!G33 -> 0.13725969 | H14: ='3 Statement Model'!H33 -> 0.14768945 | I14: ='3 Statement Model'!I33 -> 0.10600255 | J14: ='3 Statement Model'!J33 -> 0.121644 | ... L14: ='3 Statement Model'!L33 -> 0.10941283 | N14: =AVERAGE(C14:L14) -> 0.12758609 | O14: =MEDIAN(C14:L14) -> 0.12432442
B16: Sales Expenses % of Sales | C16: ='3 Statement Model'!C16 -> 0.14943149 | D16: ='3 Statement Model'!D16 -> 0.15506384 | E16: ='3 Statement Model'!E16 -> 0.14421604 | F16: ='3 Statement Model'!F16 -> 0.13354276 | G16: ='3 Statement Model'!G16 -> 0.14306191 | H16: ='3 Statement Model'!H16 -> 0.12997501 | I16: ='3 Statement Model'!I16 -> 0.12738615 | J16: ='3 Statement Model'!J16 -> 0.12937757 | ... L16: ='3 Statement Model'!L16 -> 0.1521323 | N16: =AVERAGE(C16:L16) -> 0.1402229 | O16: =MEDIAN(C16:L16) -> 0.1405519
B17: Depreciation % of Sales | C17: ='3 Statement Model'!C20/'3 Statement Model'!C6 -> 0.019309827 | D17: ='3 Statement Model'!D20/'3 Statement Model'!D6 -> 0.022227475 | E17: ='3 Statement Model'!E20/'3 Statement Model'!E6 -> 0.021425239 | F17: ='3 Statement Model'!F20/'3 Statement Model'!F6 -> 0.03233554 | G17: ='3 Statement Model'!G20/'3 Statement Model'!G6 -> 0.038617107 | H17: ='3 Statement Model'!H20/'3 Statement Model'!H6 -> 0.036442576 | I17: ='3 Statement Model'!I20/'3 Statement Model'!I6 -> 0.028052374 | J17: ='3 Statement Model'!J20/'3 Statement Model'!J6 -> 0.024878373 | ... L17: ='3 Statement Model'!L20/'3 Statement Model'!L6 -> 0.030270498 | N17: =AVERAGE(C17:L17) -> 0.027759074 | O17: =MEDIAN(C17:L17) -> 0.026465374
B18: Operating income % of Sales | C18: ='3 Statement Model'!C22/'3 Statement Model'!C6 -> 0.1716331 | D18: ='3 Statement Model'!D22/'3 Statement Model'!D6 -> 0.17653511 | E18: ='3 Statement Model'!E22/'3 Statement Model'!E6 -> 0.16901136 | F18: ='3 Statement Model'!F22/'3 Statement Model'!F6 -> 0.16334609 | G18: ='3 Statement Model'!G22/'3 Statement Model'!G6 -> 0.16729643 | H18: ='3 Statement Model'!H22/'3 Statement Model'!H6 -> 0.18718599 | I18: ='3 Statement Model'!I22/'3 Statement Model'!I6 -> 0.13701287 | J18: ='3 Statement Model'!J22/'3 Statement Model'!J6 -> 0.15662629 | ... L18: ='3 Statement Model'!L22/'3 Statement Model'!L6 -> 0.14687447 | N18: =AVERAGE(C18:L18) -> 0.16651831 | O18: =MEDIAN(C18:L18) -> 0.16815389
B20: Return on Capital Employed | C20: ='3 Statement Model'!C22/SUM('3 Statement Model'!C46:C48) -> 0.35768409 | D20: ='3 Statement Model'!D22/SUM('3 Statement Model'!D46:D48) -> 0.32568534 | E20: ='3 Statement Model'!E22/SUM('3 Statement Model'!E46:E48) -> 0.31793919 | F20: ='3 Statement Model'!F22/SUM('3 Statement Model'!F46:F48) -> 0.29126565 | G20: ='3 Statement Model'!G22/SUM('3 Statement Model'!G46:G48) -> 0.30059314 | H20: ='3 Statement Model'!H22/SUM('3 Statement Model'!H46:H48) -> 0.29241025 | I20: ='3 Statement Model'!I22/SUM('3 Statement Model'!I46:I48) -> 0.25893857 | J20: ='3 Statement Model'!J22/SUM('3 Statement Model'!J46:J48) -> 0.30135929 | ... L20: ='3 Statement Model'!L22/SUM('3 Statement Model'!L46:L48) -> 0.22959184 | N20: =AVERAGE(C20:L20) -> 0.29929734 | O20: =MEDIAN(C20:L20) -> 0.30097621
B21: Retained Earnings % | C21: ='3 Statement Model'!C42 -> 0.59341231 | D21: ='3 Statement Model'!D42 -> 0.50999132 | E21: ='3 Statement Model'!E42 -> 0.6021492 | F21: ='3 Statement Model'!F42 -> 0.54386696 | G21: ='3 Statement Model'!G42 -> 0.5850897 | H21: ='3 Statement Model'!H42 -> 0.46607313 | I21: ='3 Statement Model'!I42 -> 0.40454355 | J21: ='3 Statement Model'!J42 -> 0.4135503 | ... L21: ='3 Statement Model'!L42 -> 0.3587585 | N21: =AVERAGE(C21:L21) -> 0.49027106 | O21: =MEDIAN(C21:L21) -> 0.48803222
B22: Return on Equity % | C22: ='3 Statement Model'!C32/SUM('3 Statement Model'!C46:C47) -> 0.27117376 | D22: ='3 Statement Model'!D32/SUM('3 Statement Model'!D46:D47) -> 0.26516033 | E22: ='3 Statement Model'!E32/SUM('3 Statement Model'!E46:E47) -> 0.24940103 | F22: ='3 Statement Model'!F32/SUM('3 Statement Model'!F46:F47) -> 0.23314802 | G22: ='3 Statement Model'!G32/SUM('3 Statement Model'!G46:G47) -> 0.27385451 | H22: ='3 Statement Model'!H32/SUM('3 Statement Model'!H46:H47) -> 0.25040429 | I22: ='3 Statement Model'!I32/SUM('3 Statement Model'!I46:I47) -> 0.22334986 | J22: ='3 Statement Model'!J32/SUM('3 Statement Model'!J46:J47) -> 0.26233552 | ... L22: ='3 Statement Model'!L32/SUM('3 Statement Model'!L46:L47) -> 0.19122404 | N22: =AVERAGE(C22:L22) -> 0.25168049 | O22: =MEDIAN(C22:L22) -> 0.25636991
B23: Self Sustained growth rate | C23: =C21*C22 -> 0.16091785 | D23: =D21*D22 -> 0.13522947 | E23: =E21*E22 -> 0.15017663 | F23: =F21*F22 -> 0.12680151 | G23: =G21*G22 -> 0.16022945 | H23: =H21*H22 -> 0.11670671 | I23: =I21*I22 -> 0.090354746 | J23: =J21*J22 -> 0.10848893 | ... L23: =L21*L22 -> 0.068603249 | N23: =AVERAGE(C23:L23) -> 0.12437106 | O23: =MEDIAN(C23:L23) -> 0.12650178
B24: Interest coverage ratio | C24: ='3 Statement Model'!C22/'3 Statement Model'!C24 -> 49.98898 | D24: ='3 Statement Model'!D22/'3 Statement Model'!D24 -> 71.22877 | E24: ='3 Statement Model'!E22/'3 Statement Model'!E24 -> 68.568604 | F24: ='3 Statement Model'!F22/'3 Statement Model'!F24 -> 28.449353 | G24: ='3 Statement Model'!G22/'3 Statement Model'!G24 -> 33.042803 | H24: ='3 Statement Model'!H22/'3 Statement Model'!H24 -> 44.355888 | I24: ='3 Statement Model'!I22/'3 Statement Model'!I24 -> 41.790693 | J24: ='3 Statement Model'!J22/'3 Statement Model'!J24 -> 37.395777 | ... L24: ='3 Statement Model'!L22/'3 Statement Model'!L24 -> 21.935821 | N24: =AVERAGE(C24:L24) -> 42.95684 | O24: =MEDIAN(C24:L24) -> 39.593235
